Workbook

Sheet CRN
A1: S | N | B1: INSURED NAME | C1: CATEGORY | D1: CLIENT CODE | E1: CRN | F1: CLIENT NAME | G1: CLAIM NUMBER | H1: CASE RECIPET DATE | I1: RECIPET MONTH | J1: INSURED | K1: 134 NOTICE | L1: CLAIMANT | M1: INCOME | N1: DRIVER | O1: DL | P1: RC | Q1: PERMIT | R1: SPOT | S1: COURT | T1: NOTICE | U1: RTI | V1: HOSPITAL | W1: WITNESS | X1: MEDICAL VERIFICATION | Y1: TOTAl | Z1: WT
A2: 1 | B2: Inderdeep Construction Company | C2: MACT | D2: M002 | E2: M002-1001-SS-2025 | F2: =IF(D2="", "", _xlfn.XLOOKUP(D2, CLIENT_CODE!D:D, CLIENT_CODE!B:B, "")) -> Magma HDI General Insurance Company Ltd | G2: C2264103101203-00 | H2: 45873 | I2: =IF(ISBLANK(H2), "", TEXT(H2, "mmm-yy")) -> Aug-25 | J2: 1 | K2: 0 | L2: 1 | M2: 0 | N2: 1 | O2: 0 | P2: 0 | Q2: 0 | R2: 1 | S2: 1 | T2: 0 | U2: 0 | V2: 0 | W2: 0 | X2: 0 | Y2: =IF(COUNTA(J2:T2)=0, "", SUM(J2:T2)) -> 5 | Z2: {=_xlfn._xlws.FILTER(MIS_Backend_Data!L:L,MIS_Backend_Data!L:L="WT")} -> WT
A3: 2 | B3: Chandrabhaga Shivaji Pawar VS MAGMA | C3: MACT | D3: M002 | E3: M002-1002-SS-2025 | F3: =IF(D3="", "", _xlfn.XLOOKUP(D3, CLIENT_CODE!D:D, CLIENT_CODE!B:B, "")) -> Magma HDI General Insurance Company Ltd | G3: C2264191100006-00 | H3: 45873 | I3: =IF(ISBLANK(H3), "", TEXT(H3, "mmm-yy")) -> Aug-25 | J3: 1 | K3: 0 | L3: 1 | M3: 0 | N3: 1 | O3: 0 | P3: 0 | Q3: 0 | R3: 1 | S3: 1 | T3: 0 | U3: 0 | V3: 0 | W3: 0 | X3: 0 | Y3: =IF(COUNTA(J3:T3)=0, "", SUM(J3:T3)) -> 5 | Z3: WT
A4: 3 | B4: Balu Motiram Wagh VS MAGMA | C4: MACT | D4: M002 | E4: M002-1003-SS-2025 | F4: =IF(D4="", "", _xlfn.XLOOKUP(D4, CLIENT_CODE!D:D, CLIENT_CODE!B:B, "")) -> Magma HDI General Insurance Company Ltd | G4: C2264103101217-04 | H4: 45876 | I4: =IF(ISBLANK(H4), "", TEXT(H4, "mmm-yy")) -> Aug-25 | J4: 1 | K4: 0 | L4: 1 | M4: 0 | N4: 1 | O4: 0 | P4: 0 | Q4: 0 | R4: 1 | S4: 1 | T4: 0 | U4: 0 | V4: 0 | W4: 0 | X4: 0 | Y4: =IF(COUNTA(J4:T4)=0, "", SUM(J4:T4)) -> 5 | Z4: WT
A5: 4 | B5: Salim Ajgarali Sayyad | C5: MACT | D5: F001 | E5: F001-1004-SS-2025 | F5: =IF(D5="", "", _xlfn.XLOOKUP(D5, CLIENT_CODE!D:D, CLIENT_CODE!B:B, "")) -> Generali Central Insurance Company Limited | G5: MTP-N-2526-002724 | H5: 45890 | I5: =IF(ISBLANK(H5), "", TEXT(H5, "mmm-yy")) -> Aug-25 | J5: 1 | K5: 0 | L5: 1 | M5: 1 | N5: 1 | O5: 1 | P5: 1 | Q5: 0 | R5: 1 | S5: 1 | T5: 0 | U5: 0 | V5: 0 | W5: 0 | X5: 0 | Y5: =IF(COUNTA(J5:T5)=0, "", SUM(J5:T5)) -> 8 | Z5: WT
A6: 5 | B6: NA | C6: MACT | D6: F001 | E6: F001-1005-SS-2025 | F6: =IF(D6="", "", _xlfn.XLOOKUP(D6, CLIENT_CODE!D:D, CLIENT_CODE!B:B, "")) -> Generali Central Insurance Company Limited | G6: MTP-N-2526-002725 | H6: 45890 | I6: =IF(ISBLANK(H6), "", TEXT(H6, "mmm-yy")) -> Aug-25 | J6: 1 | K6: 0 | L6: 0 | M6: 0 | N6: 0 | O6: 0 | P6: 0 | Q6: 0 | R6: 0 | S6: 0 | T6: 0 | U6: 0 | V6: 0 | W6: 0 | X6: 0 | Y6: =IF(COUNTA(J6:T6)=0, "", SUM(J6:T6)) -> 1 | Z6: WT
A7: 6 | B7: NA | C7: MACT | D7: F001 | E7: F001-1006-SS-2025 | F7: =IF(D7="", "", _xlfn.XLOOKUP(D7, CLIENT_CODE!D:D, CLIENT_CODE!B:B, "")) -> Generali Central Insurance Company Limited | G7: MTP-N-2526-002726 | H7: 45890 | I7: =IF(ISBLANK(H7), "", TEXT(H7, "mmm-yy")) -> Aug-25 | J7: 1 | K7: 0 | L7: 0 | M7: 0 | N7: 0 | O7: 0 | P7: 0 | Q7: 0 | R7: 0 | S7: 0 | T7: 0 | U7: 0 | V7: 0 | W7: 0 | X7: 0 | Y7: =IF(COUNTA(J7:T7)=0, "", SUM(J7:T7)) -> 1 | Z7: WT
A8: 7 | B8: Gajanan Wishvanath Kapuskari | C8: MACT | D8: F001 | E8: F001-1007-SS-2025 | F8: =IF(D8="", "", _xlfn.XLOOKUP(D8, CLIENT_CODE!D:D, CLIENT_CODE!B:B, "")) -> Generali Central Insurance Company Limited | G8: MTP-N-2526-002845 | H8: 45897 | I8: =IF(ISBLANK(H8), "", TEXT(H8, "mmm-yy")) -> Aug-25 | J8: 1 | K8: 0 | L8: 0 | M8: 0 | N8: 1 | O8: 1 | P8: 1 | Q8: 1 | R8: 1 | S8: 1 | T8: 0 | U8: 0 | V8: 0 | W8: 0 | X8: 0 | Y8: =IF(COUNTA(J8:T8)=0, "", SUM(J8:T8)) -> 7 | Z8: WT
A9: 8 | B9: GorakhDamu Godage | C9: MACT | D9: F001 | E9: F001-1008-SS-2025 | F9: =IF(D9="", "", _xlfn.XLOOKUP(D9, CLIENT_CODE!D:D, CLIENT_CODE!B:B, "")) -> Generali Central Insurance Company Limited | G9: MTP-N-2526-003010 | H9: 45902 | I9: =IF(ISBLANK(H9), "", TEXT(H9, "mmm-yy")) -> Sep-25 | J9: 1 | K9: 0 | L9: 1 | M9: 1 | N9: 1 | O9: 1 | P9: 1 | Q9: 0 | R9: 1 | S9: 1 | T9: 0 | U9: 0 | V9: 0 | W9: 0 | X9: 0 | Y9: =IF(COUNTA(J9:T9)=0, "", SUM(J9:T9)) -> 8 | Z9: WT
A10: 9 | B10: Sharad RaoSaheb Pathare | C10: MACT | D10: R001 | E10: R001-1009-SS-2025 | F10: =IF(D10="", "", _xlfn.XLOOKUP(D10, CLIENT_CODE!D:D, CLIENT_CODE!B:B, "")) -> Indusind General Insurance Co Ltd | G10: 2025209111 | H10: 45916 | I10: =IF(ISBLANK(H10), "", TEXT(H10, "mmm-yy")) -> Sep-25 | J10: 1 | K10: 0 | L10: 1 | M10: 0 | N10: 1 | O10: 0 | P10: 0 | Q10: 0 | R10: 1 | S10: 1 | T10: 0 | U10: 0 | V10: 0 | W10: 0 | X10: 0 | Y10: =IF(COUNTA(J10:T10)=0, "", SUM(J10:T10)) -> 5 | Z10: WT
A11: 10 | B11: Ravindra Pandurang Patil | C11: MACT | D11: F001 | E11: F001-1010-SS-2025 | F11: =IF(D11="", "", _xlfn.XLOOKUP(D11, CLIENT_CODE!D:D, CLIENT_CODE!B:B, "")) -> Generali Central Insurance Company Limited | G11: CN064878 | H11: 45916 | I11: =IF(ISBLANK(H11), "", TEXT(H11, "mmm-yy")) -> Sep-25 | J11: 0 | K11: 0 | L11: 1 | M11: 0 | N11: 1 | O11: 0 | P11: 0 | Q11: O | R11: 1 | S11: 1 | T11: 0 | U11: 0 | V11: 1 | W11: 0 | X11: 0 | Y11: =IF(COUNTA(J11:T11)=0, "", SUM(J11:T11)) -> 4 | Z11: WT
A12: 11 | B12: Navnath Jagannatrh Navgire | C12: MACT | D12: R001 | E12: R001-1011-SS-2025 | F12: =IF(D12="", "", _xlfn.XLOOKUP(D12, CLIENT_CODE!D:D, CLIENT_CODE!B:B, "")) -> Indusind General Insurance Co Ltd | G12: 2025201119 | H12: 45916 | I12: =IF(ISBLANK(H12), "", TEXT(H12, "mmm-yy")) -> Sep-25 | J12: 0 | K12: 0 | L12: 0 | M12: 0 | N12: 0 | O12: 0 | P12: 0 | Q12: 0 | R12: 0 | S12: 1 | T12: 0 | U12: 0 | V12: 0 | W12: 0 | X12: 0 | Y12: =IF(COUNTA(J12:T12)=0, "", SUM(J12:T12)) -> 1 | Z12: WT
A13: 12 | B13: Sunil Annasaheb Kulat | C13: MACT | D13: R001 | E13: R001-1012-SS-2025 | F13: =IF(D13="", "", _xlfn.XLOOKUP(D13, CLIENT_CODE!D:D, CLIENT_CODE!B:B, "")) -> Indusind General Insurance Co Ltd | G13: 2025210107 | H13: 45917 | I13: =IF(ISBLANK(H13), "", TEXT(H13, "mmm-yy")) -> Sep-25 | J13: 1 | K13: 0 | L13: 1 | M13: 0 | N13: 1 | O13: 0 | P13: 0 | Q13: 0 | R13: 1 | S13: 1 | T13: 0 | U13: 0 | V13: 0 | W13: 0 | X13: 0 | Y13: =IF(COUNTA(J13:T13)=0, "", SUM(J13:T13)) -> 5 | Z13: WT
A14: 13 | B14: NA | C14: MACT | D14: R001 | E14: R001-1013-SS-2025 | F14: =IF(D14="", "", _xlfn.XLOOKUP(D14, CLIENT_CODE!D:D, CLIENT_CODE!B:B, "")) -> Indusind General Insurance Co Ltd | G14: 2025209818 | H14: 45917 | I14: =IF(ISBLANK(H14), "", TEXT(H14, "mmm-yy")) -> Sep-25 | J14: 0 | K14: 0 | L14: 1 | M14: 0 | N14: 0 | O14: 0 | P14: 0 | Q14: 0 | R14: 0 | S14: 0 | T14: 0 | U14: 0 | V14: 0 | W14: 0 | X14: 0 | Y14: =IF(COUNTA(J14:T14)=0, "", SUM(J14:T14)) -> 1 | Z14: WT
A15: 14 | B15: Dilip Parshuram Salukhe | C15: MACT | D15: R001 | E15: R001-1014-SS-2025 | F15: =IF(D15="", "", _xlfn.XLOOKUP(D15, CLIENT_CODE!D:D, CLIENT_CODE!B:B, "")) -> Indusind General Insurance Co Ltd | G15: 2025210174 | H15: 45917 | I15: =IF(ISBLANK(H15), "", TEXT(H15, "mmm-yy")) -> Sep-25 | J15: 1 | K15: 0 | L15: 1 | M15: 0 | N15: 1 | O15: 0 | P15: 0 | Q15: 0 | R15: 1 | S15: 1 | T15: 0 | U15: 0 | V15: 0 | W15: 0 | X15: 0 | Y15: =IF(COUNTA(J15:T15)=0, "", SUM(J15:T15)) -> 5 | Z15: WT
A16: 15 | B16: Jitendra Dyaneshwar Naik | C16: MACT | D16: R001 | E16: R001-1015-SS-2025 | F16: =IF(D16="", "", _xlfn.XLOOKUP(D16, CLIENT_CODE!D:D, CLIENT_CODE!B:B, "")) -> Indusind General Insurance Co Ltd | G16: 2025210104 | H16: 45917 | I16: =IF(ISBLANK(H16), "", TEXT(H16, "mmm-yy")) -> Sep-25 | J16: 0 | K16: 0 | L16: 1 | M16: 0 | N16: 0 | O16: 0 | P16: 0 | Q16: 0 | R16: 0 | S16: 1 | T16: 0 | U16: 0 | V16: 0 | W16: 0 | X16: 0 | Y16: =IF(COUNTA(J16:T16)=0, "", SUM(J16:T16)) -> 2 | Z16: WT
A17: 16 | B17: Uday Bapurao Devekar | C17: MACT | D17: R001 | E17: R001-1016-SS-2025 | F17: =IF(D17="", "", _xlfn.XLOOKUP(D17, CLIENT_CODE!D:D, CLIENT_CODE!B:B, "")) -> Indusind General Insurance Co Ltd | G17: 2025209654 | H17: 45917 | I17: =IF(ISBLANK(H17), "", TEXT(H17, "mmm-yy")) -> Sep-25 | J17: 1 | K17: 0 | L17: 1 | M17: 0 | N17: 1 | O17: 0 | P17: 0 | Q17: 0 | R17: 1 | S17: 1 | T17: 0 | U17: 0 | V17: 0 | W17: 0 | X17: 0 | Y17: =IF(COUNTA(J17:T17)=0, "", SUM(J17:T17)) -> 5 | Z17: WT
A18: 17 | B18: Mahadev Vayankat Panchal | C18: MACT | D18: R001 | E18: R001-1017-SS-2025 | F18: =IF(D18="", "", _xlfn.XLOOKUP(D18, CLIENT_CODE!D:D, CLIENT_CODE!B:B, "")) -> Indusind General Insurance Co Ltd | G18: 2025209769 | H18: 45917 | I18: =IF(ISBLANK(H18), "", TEXT(H18, "mmm-yy")) -> Sep-25 | J18: 1 | K18: 0 | L18: 1 | M18: 0 | N18: 1 | O18: 0 | P18: 0 | Q18: 0 | R18: 1 | S18: 1 | T18: 0 | U18: 0 | V18: 0 | W18: 0 | X18: 0 | Y18: =IF(COUNTA(J18:T18)=0, "", SUM(J18:T18)) -> 5 | Z18: WT
A19: 18 | B19: Chand Babu Israr Ahmad Khan | C19: MACT | D19: F001 | E19: F001-1018-SS-2025 | F19: =IF(D19="", "", _xlfn.XLOOKUP(D19, CLIENT_CODE!D:D, CLIENT_CODE!B:B, "")) -> Generali Central Insurance Company Limited | G19: CN065449 | H19: 45917 | I19: =IF(ISBLANK(H19), "", TEXT(H19, "mmm-yy")) -> Sep-25 | J19: 0 | K19: 0 | L19: 1 | M19: 1 | N19: 0 | O19: 1 | P19: 1 | Q19: 0 | R19: 0 | S19: 1 | T19: 0 | U19: 0 | V19: 1 | W19: 0 | X19: 0 | Y19: =IF(COUNTA(J19:T19)=0, "", SUM(J19:T19)) -> 5 | Z19: WT
A20: 19 | B20: Chand Babu Israr Ahmad Khan | C20: MACT | D20: F001 | E20: F001-1019-SS-2025 | F20: =IF(D20="", "", _xlfn.XLOOKUP(D20, CLIENT_CODE!D:D, CLIENT_CODE!B:B, "")) -> Generali Central Insurance Company Limited | G20: MTP-N-2526-003270 | H20: 45917 | I20: =IF(ISBLANK(H20), "", TEXT(H20, "mmm-yy")) -> Sep-25 | J20: 0 | K20: 0 | L20: 1 | M20: 1 | N20: 0 | O20: 0 | P20: 0 | Q20: 0 | R20: 0 | S20: 0 | T20: 0 | U20: 0 | V20: 1 | W20: 0 | X20: 0 | Y20: =IF(COUNTA(J20:T20)=0, "", SUM(J20:T20)) -> 2 | Z20: WT
A21: 20 | B21: Chand Babu Israr Ahmad Khan | C21: MACT | D21: F001 | E21: F001-1020-SS-2025 | F21: =IF(D21="", "", _xlfn.XLOOKUP(D21, CLIENT_CODE!D:D, CLIENT_CODE!B:B, "")) -> Generali Central Insurance Company Limited | G21: MTP-N-2526-003272 | H21: 45917 | I21: =IF(ISBLANK(H21), "", TEXT(H21, "mmm-yy")) -> Sep-25 | J21: 0 | K21: 0 | L21: 1 | M21: 1 | N21: 0 | O21: 0 | P21: 0 | Q21: 0 | R21: 0 | S21: 0 | T21: 0 | U21: 0 | V21: 1 | W21: 0 | X21: 0 | Y21: =IF(COUNTA(J21:T21)=0, "", SUM(J21:T21)) -> 2 | Z21: WT
A22: 21 | B22: HOUSRAO DASHRATH JAYBHAY | C22: MACT | D22: M002 | E22: M002-1021-SS-2025 | F22: =IF(D22="", "", _xlfn.XLOOKUP(D22, CLIENT_CODE!D:D, CLIENT_CODE!B:B, "")) -> Magma HDI General Insurance Company Ltd | G22: C2254103102949-00 | H22: 45734 | I22: =IF(ISBLANK(H22), "", TEXT(H22, "mmm-yy")) -> Mar-25 | J22: 1 | K22: 0 | L22: 1 | M22: 0 | N22: 1 | O22: 0 | P22: 0 | Q22: 0 | R22: 1 | S22: 1 | T22: 0 | U22: 0 | V22: 0 | W22: 0 | X22: 0 | Y22: =IF(COUNTA(J22:T22)=0, "", SUM(J22:T22)) -> 5 | Z22: WT
A23: 22 | B23: Ramchand Bhagchand Bhandare 9823327788 | C23: MACT | D23: R001 | E23: R001-1022-SS-2025 | F23: =IF(D23="", "", _xlfn.XLOOKUP(D23, CLIENT_CODE!D:D, CLIENT_CODE!B:B, "")) -> Indusind General Insurance Co Ltd | G23: 2024214888 | H23: 45918 | I23: =IF(ISBLANK(H23), "", TEXT(H23, "mmm-yy")) -> Sep-25 | J23: 1 | K23: 0 | L23: 1 | M23: 0 | N23: 1 | O23: 0 | P23: 0 | Q23: 0 | R23: 1 | S23: 1 | T23: 0 | U23: 0 | V23: 0 | W23: 0 | X23: 0 | Y23: =IF(COUNTA(J23:T23)=0, "", SUM(J23:T23)) -> 5 | Z23: WT
... A37: 36 | B37: Shrinivas Narsing Pal 7777072902 | C37: MACT | D37: R001 | E37: R001-1036-SS-2025 | F37: =IF(D37="", "", _xlfn.XLOOKUP(D37, CLIENT_CODE!D:D, CLIENT_CODE!B:B, "")) -> Indusind General Insurance Co Ltd | G37: 2025211458 | H37: 45944 | I37: =IF(ISBLANK(H37), "", TEXT(H37, "mmm-yy")) -> Oct-25 | J37: 1 | K37: 0 | L37: 1 | M37: 0 | N37: 1 | O37: 0 | P37: 0 | Q37: 0 | R37: 1 | S37: 1 | T37: 0 | U37: 0 | V37: 0 | W37: 0 | X37: 0 | Y37: =IF(COUNTA(J37:T37)=0, "", SUM(J37:T37)) -> 5 | Z37: WT
A38: 37 | B38: Aksha Ramesh Pawar | C38: MACT | D38: R001 | E38: R001-1037-SS-2025 | F38: =IF(D38="", "", _xlfn.XLOOKUP(D38, CLIENT_CODE!D:D, CLIENT_CODE!B:B, "")) -> Indusind General Insurance Co Ltd | G38: 2025211454 | H38: 45944 | I38: =IF(ISBLANK(H38), "", TEXT(H38, "mmm-yy")) -> Oct-25 | J38: S | K38: 0 | L38: 1 | M38: 0 | N38: 1 | O38: 0 | P38: 0 | Q38: 0 | R38: 1 | S38: 1 | T38: 0 | U38: 0 | V38: 0 | W38: 0 | X38: 0 | Y38: =IF(COUNTA(J38:T38)=0, "", SUM(J38:T38)) -> 4 | Z38: WT
A39: 38 | B39: Lalaji Manikrao Dhonde @ Dhande | C39: MACT | D39: R001 | E39: R001-1038-SS-2025 | F39: =IF(D39="", "", _xlfn.XLOOKUP(D39, CLIENT_CODE!D:D, CLIENT_CODE!B:B, "")) -> Indusind General Insurance Co Ltd | G39: 2025211475 | H39: 45946 | I39: =IF(ISBLANK(H39), "", TEXT(H39, "mmm-yy")) -> Oct-25 | J39: 1 | K39: 0 | L39: 1 | M39: 0 | N39: 1 | O39: 0 | P39: 0 | Q39: 0 | R39: 1 | S39: 1 | T39: 0 | U39: 0 | V39: 0 | W39: 0 | X39: 0 | Y39: =IF(COUNTA(J39:T39)=0, "", SUM(J39:T39)) -> 5 | Z39: WT
A40: 39 | B40: Ajay Satyanarayan Totawar | C40: MACT | D40: R001 | E40: R001-1039-SS-2025 | F40: =IF(D40="", "", _xlfn.XLOOKUP(D40, CLIENT_CODE!D:D, CLIENT_CODE!B:B, "")) -> Indusind General Insurance Co Ltd | G40: 2025211478 | H40: 45946 | I40: =IF(ISBLANK(H40), "", TEXT(H40, "mmm-yy")) -> Oct-25 | J40: 1 | K40: 0 | L40: 1 | M40: 0 | N40: 1 | O40: 0 | P40: 0 | Q40: 0 | R40: 1 | S40: 1 | T40: 0 | U40: 0 | V40: 0 | W40: 0 | X40: 0 | Y40: =IF(COUNTA(J40:T40)=0, "", SUM(J40:T40)) -> 5 | Z40: WT
A41: 40 | B41: Sanjay Sudam Gadgul | C41: MACT | D41: R001 | E41: R001-1040-SS-2025 | F41: =IF(D41="", "", _xlfn.XLOOKUP(D41, CLIENT_CODE!D:D, CLIENT_CODE!B:B, "")) -> Indusind General Insurance Co Ltd | G41: 2025210709 | H41: 45946 | I41: =IF(ISBLANK(H41), "", TEXT(H41, "mmm-yy")) -> Oct-25 | J41: 1 | K41: 0 | L41: 1 | M41: 0 | N41: 0 | O41: 0 | P41: 0 | Q41: 0 | R41: 1 | S41: 0 | T41: 0 | U41: 0 | V41: 0 | W41: 0 | X41: 0 | Y41: =IF(COUNTA(J41:T41)=0, "", SUM(J41:T41)) -> 3 | Z41: WT
A42: 41 | B42: Umesh Govinda Gavli | C42: MACT | D42: F001 | E42: F001-1041-SS-2025 | F42: =IF(D42="", "", _xlfn.XLOOKUP(D42, CLIENT_CODE!D:D, CLIENT_CODE!B:B, "")) -> Generali Central Insurance Company Limited | G42: CN066141 | H42: 45957 | I42: =IF(ISBLANK(H42), "", TEXT(H42, "mmm-yy")) -> Oct-25 | J42: 0 | K42: 0 | L42: 0 | M42: 0 | N42: 0 | O42: 0 | P42: 0 | Q42: 0 | R42: 0 | S42: 0 | T42: 0 | U42: 0 | V42: 1 | W42: 0 | X42: 0 | Y42: =IF(COUNTA(J42:T42)=0, "", SUM(J42:T42)) -> 0 | Z42: WT
A43: 42 | B43: Ranjeet Lala Chavan | C43: MACT | D43: F001 | E43: F001-1042-SS-2025 | F43: =IF(D43="", "", _xlfn.XLOOKUP(D43, CLIENT_CODE!D:D, CLIENT_CODE!B:B, "")) -> Generali Central Insurance Company Limited | G43: MTP-N-2526-004127 | H43: 45960 | I43: =IF(ISBLANK(H43), "", TEXT(H43, "mmm-yy")) -> Oct-25 | J43: 1 | K43: 0 | L43: 1 | M43: 1 | N43: 1 | O43: 1 | P43: 1 | Q43: 0 | R43: 1 | S43: 1 | T43: 0 | U43: 0 | V43: 1 | W43: 0 | X43: 0 | Y43: =IF(COUNTA(J43:T43)=0, "", SUM(J43:T43)) -> 8 | Z43: WT
A44: 43 | B44: NA | C44: MACT | D44: R001 | E44: R001-1043-SS-2025 | F44: =IF(D44="", "", _xlfn.XLOOKUP(D44, CLIENT_CODE!D:D, CLIENT_CODE!B:B, "")) -> Indusind General Insurance Co Ltd | G44: 2025212071 | H44: 45961 | I44: =IF(ISBLANK(H44), "", TEXT(H44, "mmm-yy")) -> Oct-25 | J44: 0 | K44: 0 | L44: 1 | M44: 0 | N44: 0 | O44: 0 | P44: 0 | Q44: 0 | R44: 0 | S44: 0 | T44: 0 | U44: 0 | V44: 0 | W44: 0 | X44: 0 | Y44: =IF(COUNTA(J44:T44)=0, "", SUM(J44:T44)) -> 1 | Z44: WT
A45: 44 | B45: Kakasaheb Shrirang Dhumal | C45: MACT | D45: R001 | E45: R001-1044-SS-2025 | F45: =IF(D45="", "", _xlfn.XLOOKUP(D45, CLIENT_CODE!D:D, CLIENT_CODE!B:B, "")) -> Indusind General Insurance Co Ltd | G45: 2025212068 | H45: 45961 | I45: =IF(ISBLANK(H45), "", TEXT(H45, "mmm-yy")) -> Oct-25 | J45: 1 | K45: 0 | L45: 1 | M45: 1 | N45: 0 | O45: 0 | P45: 0 | Q45: 0 | R45: 1 | S45: 1 | T45: 0 | U45: 0 | V45: 0 | W45: 0 | X45: 0 | Y45: =IF(COUNTA(J45:T45)=0, "", SUM(J45:T45)) -> 5 | Z45: WT
A46: 45 | B46: S. CUBE INFRASTRUCTURE | C46: MACT | D46: R001 | E46: R001-1045-SS-2025 | F46: =IF(D46="", "", _xlfn.XLOOKUP(D46, CLIENT_CODE!D:D, CLIENT_CODE!B:B, "")) -> Indusind General Insurance Co Ltd | G46: 2025212058 | H46: 45961 | I46: =IF(ISBLANK(H46), "", TEXT(H46, "mmm-yy")) -> Oct-25 | J46: 1 | K46: 0 | L46: 1 | M46: 0 | N46: 1 | O46: 0 | P46: 0 | Q46: 0 | R46: 1 | S46: 1 | T46: 0 | U46: 0 | V46: 0 | W46: 0 | X46: 0 | Y46: =IF(COUNTA(J46:T46)=0, "", SUM(J46:T46)) -> 5 | Z46: WT
A47: 46 | B47: NA | C47: MACT | D47: R001 | E47: R001-1046-SS-2025 | F47: =IF(D47="", "", _xlfn.XLOOKUP(D47, CLIENT_CODE!D:D, CLIENT_CODE!B:B, "")) -> Indusind General Insurance Co Ltd | G47: 2025212055 | H47: 45961 | I47: =IF(ISBLANK(H47), "", TEXT(H47, "mmm-yy")) -> Oct-25 | J47: 0 | K47: 0 | L47: 1 | M47: 0 | N47: 0 | O47: 0 | P47: 0 | Q47: 0 | R47: 0 | S47: 0 | T47: 0 | U47: 0 | V47: 0 | W47: 0 | X47: 0 | Y47: =IF(COUNTA(J47:T47)=0, "", SUM(J47:T47)) -> 1 | Z47: WT
A48: 47 | B48: Umesh Laxman Sathe | C48: MACT | D48: R001 | E48: R001-1047-SS-2025 | F48: =IF(D48="", "", _xlfn.XLOOKUP(D48, CLIENT_CODE!D:D, CLIENT_CODE!B:B, "")) -> Indusind General Insurance Co Ltd | G48: 2025212053 | H48: 45961 | I48: =IF(ISBLANK(H48), "", TEXT(H48, "mmm-yy")) -> Oct-25 | J48: 1 | K48: 0 | L48: 1 | M48: 0 | N48: 1 | O48: 0 | P48: 0 | Q48: 0 | R48: 1 | S48: 1 | T48: 0 | U48: 0 | V48: 0 | W48: 0 | X48: 0 | Y48: =IF(COUNTA(J48:T48)=0, "", SUM(J48:T48)) -> 5 | Z48: WT
A49: 48 | B49: Pravin Ashruba Andhale 9890471033 | C49: MACT | D49: R001 | E49: R001-1048-SS-2025 | F49: =IF(D49="", "", _xlfn.XLOOKUP(D49, CLIENT_CODE!D:D, CLIENT_CODE!B:B, "")) -> Indusind General Insurance Co Ltd | G49: 2025212050 | H49: 45961 | I49: =IF(ISBLANK(H49), "", TEXT(H49, "mmm-yy")) -> Oct-25 | J49: 1 | K49: 0 | L49: 1 | M49: 0 | N49: 1 | O49: 0 | P49: 0 | Q49: 0 | R49: 1 | S49: 1 | T49: 0 | U49: 0 | V49: 0 | W49: 0 | X49: 0 | Y49: =IF(COUNTA(J49:T49)=0, "", SUM(J49:T49)) -> 5 | Z49: WT
A50: 49 | B50: Rohit Dadarao Shirsath | C50: MACT | D50: R001 | E50: R001-1049-SS-2025 | F50: =IF(D50="", "", _xlfn.XLOOKUP(D50, CLIENT_CODE!D:D, CLIENT_CODE!B:B, "")) -> Indusind General Insurance Co Ltd | G50: 2025212047 | H50: 45961 | I50: =IF(ISBLANK(H50), "", TEXT(H50, "mmm-yy")) -> Oct-25 | J50: 1 | K50: 0 | L50: 1 | M50: 0 | N50: 1 | O50: 0 | P50: 0 | Q50: 0 | R50: 1 | S50: 1 | T50: 0 | U50: 0 | V50: 0 | W50: 0 | X50: 0 | Y50: =IF(COUNTA(J50:T50)=0, "", SUM(J50:T50)) -> 5 | Z50: WT
A51: 50 | B51: Vishal Kumar Goutamchand 9845320803 | C51: MACT | D51: F001 | E51: F001-1050-SS-2025 | F51: =IF(D51="", "", _xlfn.XLOOKUP(D51, CLIENT_CODE!D:D, CLIENT_CODE!B:B, "")) -> Generali Central Insurance Company Limited | G51: MTP-N-2526-004166 | H51: 45962 | I51: =IF(ISBLANK(H51), "", TEXT(H51, "mmm-yy")) -> Nov-25 | J51: 0 | K51: 0 | L51: 1 | M51: 0 | N51: 0 | O51: 0 | P51: 0 | Q51: 0 | R51: 0 | S51: 0 | T51: 0 | U51: 0 | V51: 0 | W51: 0 | X51: 0 | Z51: WT
A52: 51 | B52: Prahlad Piraji Umbre | C52: MACT | D52: R001 | E52: R001-1051-SS-2025 | F52: =IF(D52="", "", _xlfn.XLOOKUP(D52, CLIENT_CODE!D:D, CLIENT_CODE!B:B, "")) -> Indusind General Insurance Co Ltd | G52: 2025212181 | H52: 45964 | I52: =IF(ISBLANK(H52), "", TEXT(H52, "mmm-yy")) -> Nov-25 | J52: 1 | K52: 0 | L52: 1 | M52: 0 | N52: 1 | O52: 0 | P52: 0 | Q52: 0 | R52: 1 | S52: 1 | T52: 0 | U52: 0 | V52: 0 | W52: 0 | X52: 0 | Y52: =IF(COUNTA(J52:T52)=0, "", SUM(J52:T52)) -> 5 | Z52: WT
A53: 52 | B53: Bhagyashree Amol Shelke | C53: MACT | D53: R001 | E53: R001-1052-SS-2025 | F53: =IF(D53="", "", _xlfn.XLOOKUP(D53, CLIENT_CODE!D:D, CLIENT_CODE!B:B, "")) -> Indusind General Insurance Co Ltd | G53: 2025212170 | H53: 45964 | I53: =IF(ISBLANK(H53), "", TEXT(H53, "mmm-yy")) -> Nov-25 | J53: 1 | K53: 0 | L53: 1 | M53: 0 | N53: 1 | O53: 0 | P53: 0 | Q53: 0 | R53: 1 | S53: 1 | T53: 0 | U53: 0 | V53: 0 | W53: 0 | X53: 0 | Y53: =IF(COUNTA(J53:T53)=0, "", SUM(J53:T53)) -> 5 | Z53: WT
...

Sheet Ganesh
A1: S | N | B1: Cliam Number | C1: Client Name | D1: INSURED/Back | E1: Insured | F1: 134 NOTICE/Backend | G1: 134 NOTICE | H1: Claimant / Backend | I1: Claimant | J1: Income/Backend | K1: Income | L1: DRIVER/Backend | M1: Driver | N1: DL/Backend | O1: DL | P1: RC/Backend | Q1: RC | R1: PERMIT/Backend | S1: PERMIT | T1: SPOT/Backend | U1: SPOT | V1: COURT/Backend | W1: COURT | X1: NOTICE/Backend | Y1: NOTICE | Z1: RTI/Backend | AA1: RTI | AB1: Hospital/Backend | AC1: Hospital | AD1: Total
A2: 1 | B2: {=_xlfn._xlws.FILTER(MIS_Backend_Data!B:B, (MIS_Backend_Data!O:O="WIP") + (MIS_Backend_Data!O:O="Pending for CS"))} -> C2264191100006-00 | C2: {=_xlfn._xlws.FILTER(MIS_Backend_Data!#REF!, (MIS_Backend_Data!O:O="WIP") + (MIS_Backend_Data!O:O="Pending for CS"), "")} -> #REF! | D2: =_xlfn.XLOOKUP(B2,CRN!G:G,CRN!J:J,"") -> 1 | E2: =IF(D2=0,0,_xlfn.XLOOKUP(C2,CLIENT_CODE!B:B,CLIENT_CODE!F:F,0)) -> #REF! | F2: =_xlfn.XLOOKUP(B2,CRN!G:G,CRN!K:K,"") -> 0 | G2: =IF(F2=0,0,_xlfn.XLOOKUP(C2,CLIENT_CODE!B:B,CLIENT_CODE!G:G,0)) -> 0 | H2: =_xlfn.XLOOKUP(B2,CRN!G:G,CRN!L:L,"") -> 1 | I2: =IF(H2=0,0,_xlfn.XLOOKUP(C2,CLIENT_CODE!B:B,CLIENT_CODE!H:H,0)) -> #REF! | J2: =_xlfn.XLOOKUP(B2,CRN!G:G,CRN!M:M,"") -> 0 | K2: =IF(J2=0,0,_xlfn.XLOOKUP(C2,CLIENT_CODE!B:B,CLIENT_CODE!I:I,0)) -> 0 | L2: =_xlfn.XLOOKUP(B2,CRN!G:G,CRN!N:N,"") -> 1 | M2: =IF(L2=0,0,_xlfn.XLOOKUP(C2,CLIENT_CODE!B:B,CLIENT_CODE!J:J,0)) -> #REF! | N2: =_xlfn.XLOOKUP(B2,CRN!G:G,CRN!O:O,"") -> 0 | O2: =IF(N2=0,0,_xlfn.XLOOKUP(C2,CLIENT_CODE!B:B,CLIENT_CODE!K:K,0)) -> 0 | P2: =_xlfn.XLOOKUP(B2,CRN!G:G,CRN!P:P,"") -> 0 | Q2: =IF(P2=0,0,_xlfn.XLOOKUP(C2,CLIENT_CODE!B:B,CLIENT_CODE!L:L,0)) -> 0 | R2: =_xlfn.XLOOKUP(B2,CRN!G:G,CRN!Q:Q,"") -> 0 | S2: =IF(R2=0,0,_xlfn.XLOOKUP(C2,CLIENT_CODE!B:B,CLIENT_CODE!M:M,0)) -> 0 | T2: =_xlfn.XLOOKUP(B2,CRN!G:G,CRN!R:R,"") -> 1 | U2: =IF(T2=0,0,_xlfn.XLOOKUP(C2,CLIENT_CODE!B:B,CLIENT_CODE!N:N,0)) -> #REF! | V2: =_xlfn.XLOOKUP(B2,CRN!G:G,CRN!S:S,"") -> 1 | W2: =IF(V2=0,0,_xlfn.XLOOKUP(C2,CLIENT_CODE!B:B,CLIENT_CODE!O:O,0)) -> #REF! | X2: =_xlfn.XLOOKUP(B2,CRN!G:G,CRN!T:T,"") -> 0 | Y2: =IF(X2=0,0,_xlfn.XLOOKUP(C2,CLIENT_CODE!B:B,CLIENT_CODE!P:P,0)) -> 0 | Z2: =_xlfn.XLOOKUP(B2,CRN!G:G,CRN!U:U,"") -> 0 | AA2: =IF(X2=0,0,_xlfn.XLOOKUP(C2,CLIENT_CODE!B:B,CLIENT_CODE!P:P,0)) -> 0 | AB2: =_xlfn.XLOOKUP(B2,CRN!G:G,CRN!V:V,"") -> 0 | AC2: =IF(AB2=0,0,_xlfn.XLOOKUP(C2,CLIENT_CODE!B:B,CLIENT_CODE!R:R,0)) -> 0 | AD2: =SUM(E2,G2,I2,K2,M2,O2,Q2,S2,U2,W2,Y2,AA2,AC2,) -> #REF!
A3: 2 | B3: 2025209769 | E3: =IF(D3=0,0,_xlfn.XLOOKUP(C3,CLIENT_CODE!B:B,CLIENT_CODE!F:F,0)) -> 0 | F3: =_xlfn.XLOOKUP(B3,CRN!G:G,CRN!K:K,"") -> 0 | G3: =IF(F3=0,0,_xlfn.XLOOKUP(C3,CLIENT_CODE!B:B,CLIENT_CODE!G:G,0)) -> 0 | H3: =_xlfn.XLOOKUP(B3,CRN!G:G,CRN!L:L,"") -> 1 | I3: =IF(H3=0,0,_xlfn.XLOOKUP(C3,CLIENT_CODE!B:B,CLIENT_CODE!H:H,0)) -> 0 | J3: =_xlfn.XLOOKUP(B3,CRN!G:G,CRN!M:M,"") -> 0 | K3: =IF(J3=0,0,_xlfn.XLOOKUP(C3,CLIENT_CODE!B:B,CLIENT_CODE!I:I,0)) -> 0 | L3: =_xlfn.XLOOKUP(B3,CRN!G:G,CRN!N:N,"") -> 1 | M3: =IF(L3=0,0,_xlfn.XLOOKUP(C3,CLIENT_CODE!B:B,CLIENT_CODE!J:J,0)) -> 0 | N3: =_xlfn.XLOOKUP(B3,CRN!G:G,CRN!O:O,"") -> 0 | O3: =IF(N3=0,0,_xlfn.XLOOKUP(C3,CLIENT_CODE!B:B,CLIENT_CODE!K:K,0)) -> 0 | P3: =_xlfn.XLOOKUP(B3,CRN!G:G,CRN!P:P,"") -> 0 | Q3: =IF(P3=0,0,_xlfn.XLOOKUP(C3,CLIENT_CODE!B:B,CLIENT_CODE!L:L,0)) -> 0 | R3: =_xlfn.XLOOKUP(B3,CRN!G:G,CRN!Q:Q,"") -> 0 | S3: =IF(R3=0,0,_xlfn.XLOOKUP(C3,CLIENT_CODE!B:B,CLIENT_CODE!M:M,0)) -> 0 | T3: =_xlfn.XLOOKUP(B3,CRN!G:G,CRN!R:R,"") -> 1 | U3: =IF(T3=0,0,_xlfn.XLOOKUP(C3,CLIENT_CODE!B:B,CLIENT_CODE!N:N,0)) -> 0 | V3: =_xlfn.XLOOKUP(B3,CRN!G:G,CRN!S:S,"") -> 1 | W3: =IF(V3=0,0,_xlfn.XLOOKUP(C3,CLIENT_CODE!B:B,CLIENT_CODE!O:O,0)) -> 0 | X3: =_xlfn.XLOOKUP(B3,CRN!G:G,CRN!T:T,"") -> 0 | Y3: =IF(X3=0,0,_xlfn.XLOOKUP(C3,CLIENT_CODE!B:B,CLIENT_CODE!P:P,0)) -> 0 | Z3: =_xlfn.XLOOKUP(B3,CRN!G:G,CRN!U:U,"") -> 0 | AA3: =IF(X3=0,0,_xlfn.XLOOKUP(C3,CLIENT_CODE!B:B,CLIENT_CODE!P:P,0)) -> 0 | AB3: =_xlfn.XLOOKUP(B3,CRN!G:G,CRN!V:V,"") -> 0 | AC3: =IF(AB3=0,0,_xlfn.XLOOKUP(C3,CLIENT_CODE!B:B,CLIENT_CODE!R:R,0)) -> 0 | AD3: =SUM(E3,G3,I3,K3,M3,O3,Q3,S3,U3,W3,Y3,AA3,AC3,) -> 0
A4: 3 | B4: CM889835 | E4: =IF(D4=0,0,_xlfn.XLOOKUP(C4,CLIENT_CODE!B:B,CLIENT_CODE!F:F,0)) -> 0 | F4: =_xlfn.XLOOKUP(B4,CRN!G:G,CRN!K:K,"") -> 0 | G4: =IF(F4=0,0,_xlfn.XLOOKUP(C4,CLIENT_CODE!B:B,CLIENT_CODE!G:G,0)) -> 0 | H4: =_xlfn.XLOOKUP(B4,CRN!G:G,CRN!L:L,"") -> 1 | I4: =IF(H4=0,0,_xlfn.XLOOKUP(C4,CLIENT_CODE!B:B,CLIENT_CODE!H:H,0)) -> 0 | J4: =_xlfn.XLOOKUP(B4,CRN!G:G,CRN!M:M,"") -> 0 | K4: =IF(J4=0,0,_xlfn.XLOOKUP(C4,CLIENT_CODE!B:B,CLIENT_CODE!I:I,0)) -> 0 | L4: =_xlfn.XLOOKUP(B4,CRN!G:G,CRN!N:N,"") -> 0 | M4: =IF(L4=0,0,_xlfn.XLOOKUP(C4,CLIENT_CODE!B:B,CLIENT_CODE!J:J,0)) -> 0 | N4: =_xlfn.XLOOKUP(B4,CRN!G:G,CRN!O:O,"") -> 0 | O4: =IF(N4=0,0,_xlfn.XLOOKUP(C4,CLIENT_CODE!B:B,CLIENT_CODE!K:K,0)) -> 0 | P4: =_xlfn.XLOOKUP(B4,CRN!G:G,CRN!P:P,"") -> 0 | Q4: =IF(P4=0,0,_xlfn.XLOOKUP(C4,CLIENT_CODE!B:B,CLIENT_CODE!L:L,0)) -> 0 | R4: =_xlfn.XLOOKUP(B4,CRN!G:G,CRN!Q:Q,"") -> 0 | S4: =IF(R4=0,0,_xlfn.XLOOKUP(C4,CLIENT_CODE!B:B,CLIENT_CODE!M:M,0)) -> 0 | T4: =_xlfn.XLOOKUP(B4,CRN!G:G,CRN!R:R,"") -> 1 | U4: =IF(T4=0,0,_xlfn.XLOOKUP(C4,CLIENT_CODE!B:B,CLIENT_CODE!N:N,0)) -> 0 | V4: =_xlfn.XLOOKUP(B4,CRN!G:G,CRN!S:S,"") -> 1 | W4: =IF(V4=0,0,_xlfn.XLOOKUP(C4,CLIENT_CODE!B:B,CLIENT_CODE!O:O,0)) -> 0 | X4: =_xlfn.XLOOKUP(B4,CRN!G:G,CRN!T:T,"") -> 0 | Y4: =IF(X4=0,0,_xlfn.XLOOKUP(C4,CLIENT_CODE!B:B,CLIENT_CODE!P:P,0)) -> 0 | Z4: =_xlfn.XLOOKUP(B4,CRN!G:G,CRN!U:U,"") -> 0 | AA4: =IF(X4=0,0,_xlfn.XLOOKUP(C4,CLIENT_CODE!B:B,CLIENT_CODE!P:P,0)) -> 0 | AB4: =_xlfn.XLOOKUP(B4,CRN!G:G,CRN!V:V,"") -> 0 | AC4: =IF(AB4=0,0,_xlfn.XLOOKUP(C4,CLIENT_CODE!B:B,CLIENT_CODE!R:R,0)) -> 0 | AD4: =SUM(E4,G4,I4,K4,M4,O4,Q4,S4,U4,W4,Y4,AA4,AC4,) -> 0
A5: 4 | B5: 2025200573 | E5: =IF(D5=0,0,_xlfn.XLOOKUP(C5,CLIENT_CODE!B:B,CLIENT_CODE!F:F,0)) -> 0 | F5: =_xlfn.XLOOKUP(B5,CRN!G:G,CRN!K:K,"") -> 0 | G5: =IF(F5=0,0,_xlfn.XLOOKUP(C5,CLIENT_CODE!B:B,CLIENT_CODE!G:G,0)) -> 0 | H5: =_xlfn.XLOOKUP(B5,CRN!G:G,CRN!L:L,"") -> 1 | I5: =IF(H5=0,0,_xlfn.XLOOKUP(C5,CLIENT_CODE!B:B,CLIENT_CODE!H:H,0)) -> 0 | J5: =_xlfn.XLOOKUP(B5,CRN!G:G,CRN!M:M,"") -> 0 | K5: =IF(J5=0,0,_xlfn.XLOOKUP(C5,CLIENT_CODE!B:B,CLIENT_CODE!I:I,0)) -> 0 | L5: =_xlfn.XLOOKUP(B5,CRN!G:G,CRN!N:N,"") -> 1 | M5: =IF(L5=0,0,_xlfn.XLOOKUP(C5,CLIENT_CODE!B:B,CLIENT_CODE!J:J,0)) -> 0 | N5: =_xlfn.XLOOKUP(B5,CRN!G:G,CRN!O:O,"") -> 0 | O5: =IF(N5=0,0,_xlfn.XLOOKUP(C5,CLIENT_CODE!B:B,CLIENT_CODE!K:K,0)) -> 0 | P5: =_xlfn.XLOOKUP(B5,CRN!G:G,CRN!P:P,"") -> 0 | Q5: =IF(P5=0,0,_xlfn.XLOOKUP(C5,CLIENT_CODE!B:B,CLIENT_CODE!L:L,0)) -> 0 | R5: =_xlfn.XLOOKUP(B5,CRN!G:G,CRN!Q:Q,"") -> 0 | S5: =IF(R5=0,0,_xlfn.XLOOKUP(C5,CLIENT_CODE!B:B,CLIENT_CODE!M:M,0)) -> 0 | T5: =_xlfn.XLOOKUP(B5,CRN!G:G,CRN!R:R,"") -> 1 | U5: =IF(T5=0,0,_xlfn.XLOOKUP(C5,CLIENT_CODE!B:B,CLIENT_CODE!N:N,0)) -> 0 | V5: =_xlfn.XLOOKUP(B5,CRN!G:G,CRN!S:S,"") -> 1 | W5: =IF(V5=0,0,_xlfn.XLOOKUP(C5,CLIENT_CODE!B:B,CLIENT_CODE!O:O,0)) -> 0 | X5: =_xlfn.XLOOKUP(B5,CRN!G:G,CRN!T:T,"") -> 0 | Y5: =IF(X5=0,0,_xlfn.XLOOKUP(C5,CLIENT_CODE!B:B,CLIENT_CODE!P:P,0)) -> 0 | Z5: =_xlfn.XLOOKUP(B5,CRN!G:G,CRN!U:U,"") -> 0 | AA5: =IF(X5=0,0,_xlfn.XLOOKUP(C5,CLIENT_CODE!B:B,CLIENT_CODE!P:P,0)) -> 0 | AB5: =_xlfn.XLOOKUP(B5,CRN!G:G,CRN!V:V,"") -> 0 | AC5: =IF(AB5=0,0,_xlfn.XLOOKUP(C5,CLIENT_CODE!B:B,CLIENT_CODE!R:R,0)) -> 0 | AD5: =SUM(E5,G5,I5,K5,M5,O5,Q5,S5,U5,W5,Y5,AA5,AC5,) -> 0
A6: 5 | B6: 2025211134 | E6: =IF(D6=0,0,_xlfn.XLOOKUP(C6,CLIENT_CODE!B:B,CLIENT_CODE!F:F,0)) -> 0 | F6: =_xlfn.XLOOKUP(B6,CRN!G:G,CRN!K:K,"") -> 0 | G6: =IF(F6=0,0,_xlfn.XLOOKUP(C6,CLIENT_CODE!B:B,CLIENT_CODE!G:G,0)) -> 0 | H6: =_xlfn.XLOOKUP(B6,CRN!G:G,CRN!L:L,"") -> 1 | I6: =IF(H6=0,0,_xlfn.XLOOKUP(C6,CLIENT_CODE!B:B,CLIENT_CODE!H:H,0)) -> 0 | J6: =_xlfn.XLOOKUP(B6,CRN!G:G,CRN!M:M,"") -> 0 | K6: =IF(J6=0,0,_xlfn.XLOOKUP(C6,CLIENT_CODE!B:B,CLIENT_CODE!I:I,0)) -> 0 | L6: =_xlfn.XLOOKUP(B6,CRN!G:G,CRN!N:N,"") -> 1 | M6: =IF(L6=0,0,_xlfn.XLOOKUP(C6,CLIENT_CODE!B:B,CLIENT_CODE!J:J,0)) -> 0 | N6: =_xlfn.XLOOKUP(B6,CRN!G:G,CRN!O:O,"") -> 0 | O6: =IF(N6=0,0,_xlfn.XLOOKUP(C6,CLIENT_CODE!B:B,CLIENT_CODE!K:K,0)) -> 0 | P6: =_xlfn.XLOOKUP(B6,CRN!G:G,CRN!P:P,"") -> 0 | Q6: =IF(P6=0,0,_xlfn.XLOOKUP(C6,CLIENT_CODE!B:B,CLIENT_CODE!L:L,0)) -> 0 | R6: =_xlfn.XLOOKUP(B6,CRN!G:G,CRN!Q:Q,"") -> 0 | S6: =IF(R6=0,0,_xlfn.XLOOKUP(C6,CLIENT_CODE!B:B,CLIENT_CODE!M:M,0)) -> 0 | T6: =_xlfn.XLOOKUP(B6,CRN!G:G,CRN!R:R,"") -> 1 | U6: =IF(T6=0,0,_xlfn.XLOOKUP(C6,CLIENT_CODE!B:B,CLIENT_CODE!N:N,0)) -> 0 | V6: =_xlfn.XLOOKUP(B6,CRN!G:G,CRN!S:S,"") -> 1 | W6: =IF(V6=0,0,_xlfn.XLOOKUP(C6,CLIENT_CODE!B:B,CLIENT_CODE!O:O,0)) -> 0 | X6: =_xlfn.XLOOKUP(B6,CRN!G:G,CRN!T:T,"") -> 0 | Y6: =IF(X6=0,0,_xlfn.XLOOKUP(C6,CLIENT_CODE!B:B,CLIENT_CODE!P:P,0)) -> 0 | Z6: =_xlfn.XLOOKUP(B6,CRN!G:G,CRN!U:U,"") -> 0 | AA6: =IF(X6=0,0,_xlfn.XLOOKUP(C6,CLIENT_CODE!B:B,CLIENT_CODE!P:P,0)) -> 0 | AB6: =_xlfn.XLOOKUP(B6,CRN!G:G,CRN!V:V,"") -> 0 | AC6: =IF(AB6=0,0,_xlfn.XLOOKUP(C6,CLIENT_CODE!B:B,CLIENT_CODE!R:R,0)) -> 0 | AD6: =SUM(E6,G6,I6,K6,M6,O6,Q6,S6,U6,W6,Y6,AA6,AC6,) -> 0
A7: 6 | B7: 2025211454 | E7: =IF(D7=0,0,_xlfn.XLOOKUP(C7,CLIENT_CODE!B:B,CLIENT_CODE!F:F,0)) -> 0 | F7: =_xlfn.XLOOKUP(B7,CRN!G:G,CRN!K:K,"") -> 0 | G7: =IF(F7=0,0,_xlfn.XLOOKUP(C7,CLIENT_CODE!B:B,CLIENT_CODE!G:G,0)) -> 0 | H7: =_xlfn.XLOOKUP(B7,CRN!G:G,CRN!L:L,"") -> 1 | I7: =IF(H7=0,0,_xlfn.XLOOKUP(C7,CLIENT_CODE!B:B,CLIENT_CODE!H:H,0)) -> 0 | J7: =_xlfn.XLOOKUP(B7,CRN!G:G,CRN!M:M,"") -> 0 | K7: =IF(J7=0,0,_xlfn.XLOOKUP(C7,CLIENT_CODE!B:B,CLIENT_CODE!I:I,0)) -> 0 | L7: =_xlfn.XLOOKUP(B7,CRN!G:G,CRN!N:N,"") -> 1 | M7: =IF(L7=0,0,_xlfn.XLOOKUP(C7,CLIENT_CODE!B:B,CLIENT_CODE!J:J,0)) -> 0 | N7: =_xlfn.XLOOKUP(B7,CRN!G:G,CRN!O:O,"") -> 0 | O7: =IF(N7=0,0,_xlfn.XLOOKUP(C7,CLIENT_CODE!B:B,CLIENT_CODE!K:K,0)) -> 0 | P7: =_xlfn.XLOOKUP(B7,CRN!G:G,CRN!P:P,"") -> 0 | Q7: =IF(P7=0,0,_xlfn.XLOOKUP(C7,CLIENT_CODE!B:B,CLIENT_CODE!L:L,0)) -> 0 | R7: =_xlfn.XLOOKUP(B7,CRN!G:G,CRN!Q:Q,"") -> 0 | S7: =IF(R7=0,0,_xlfn.XLOOKUP(C7,CLIENT_CODE!B:B,CLIENT_CODE!M:M,0)) -> 0 | T7: =_xlfn.XLOOKUP(B7,CRN!G:G,CRN!R:R,"") -> 1 | U7: =IF(T7=0,0,_xlfn.XLOOKUP(C7,CLIENT_CODE!B:B,CLIENT_CODE!N:N,0)) -> 0 | V7: =_xlfn.XLOOKUP(B7,CRN!G:G,CRN!S:S,"") -> 1 | W7: =IF(V7=0,0,_xlfn.XLOOKUP(C7,CLIENT_CODE!B:B,CLIENT_CODE!O:O,0)) -> 0 | X7: =_xlfn.XLOOKUP(B7,CRN!G:G,CRN!T:T,"") -> 0 | Y7: =IF(X7=0,0,_xlfn.XLOOKUP(C7,CLIENT_CODE!B:B,CLIENT_CODE!P:P,0)) -> 0 | Z7: =_xlfn.XLOOKUP(B7,CRN!G:G,CRN!U:U,"") -> 0 | AA7: =IF(X7=0,0,_xlfn.XLOOKUP(C7,CLIENT_CODE!B:B,CLIENT_CODE!P:P,0)) -> 0 | AB7: =_xlfn.XLOOKUP(B7,CRN!G:G,CRN!V:V,"") -> 0 | AC7: =IF(AB7=0,0,_xlfn.XLOOKUP(C7,CLIENT_CODE!B:B,CLIENT_CODE!R:R,0)) -> 0 | AD7: =SUM(E7,G7,I7,K7,M7,O7,Q7,S7,U7,W7,Y7,AA7,AC7,) -> 0
A8: 7 | B8: 2025211475 | E8: =IF(D8=0,0,_xlfn.XLOOKUP(C8,CLIENT_CODE!B:B,CLIENT_CODE!F:F,0)) -> 0 | F8: =_xlfn.XLOOKUP(B8,CRN!G:G,CRN!K:K,"") -> 0 | G8: =IF(F8=0,0,_xlfn.XLOOKUP(C8,CLIENT_CODE!B:B,CLIENT_CODE!G:G,0)) -> 0 | H8: =_xlfn.XLOOKUP(B8,CRN!G:G,CRN!L:L,"") -> 1 | I8: =IF(H8=0,0,_xlfn.XLOOKUP(C8,CLIENT_CODE!B:B,CLIENT_CODE!H:H,0)) -> 0 | J8: =_xlfn.XLOOKUP(B8,CRN!G:G,CRN!M:M,"") -> 0 | K8: =IF(J8=0,0,_xlfn.XLOOKUP(C8,CLIENT_CODE!B:B,CLIENT_CODE!I:I,0)) -> 0 | L8: =_xlfn.XLOOKUP(B8,CRN!G:G,CRN!N:N,"") -> 1 | M8: =IF(L8=0,0,_xlfn.XLOOKUP(C8,CLIENT_CODE!B:B,CLIENT_CODE!J:J,0)) -> 0 | N8: =_xlfn.XLOOKUP(B8,CRN!G:G,CRN!O:O,"") -> 0 | O8: =IF(N8=0,0,_xlfn.XLOOKUP(C8,CLIENT_CODE!B:B,CLIENT_CODE!K:K,0)) -> 0 | P8: =_xlfn.XLOOKUP(B8,CRN!G:G,CRN!P:P,"") -> 0 | Q8: =IF(P8=0,0,_xlfn.XLOOKUP(C8,CLIENT_CODE!B:B,CLIENT_CODE!L:L,0)) -> 0 | R8: =_xlfn.XLOOKUP(B8,CRN!G:G,CRN!Q:Q,"") -> 0 | S8: =IF(R8=0,0,_xlfn.XLOOKUP(C8,CLIENT_CODE!B:B,CLIENT_CODE!M:M,0)) -> 0 | T8: =_xlfn.XLOOKUP(B8,CRN!G:G,CRN!R:R,"") -> 1 | U8: =IF(T8=0,0,_xlfn.XLOOKUP(C8,CLIENT_CODE!B:B,CLIENT_CODE!N:N,0)) -> 0 | V8: =_xlfn.XLOOKUP(B8,CRN!G:G,CRN!S:S,"") -> 1 | W8: =IF(V8=0,0,_xlfn.XLOOKUP(C8,CLIENT_CODE!B:B,CLIENT_CODE!O:O,0)) -> 0 | X8: =_xlfn.XLOOKUP(B8,CRN!G:G,CRN!T:T,"") -> 0 | Y8: =IF(X8=0,0,_xlfn.XLOOKUP(C8,CLIENT_CODE!B:B,CLIENT_CODE!P:P,0)) -> 0 | Z8: =_xlfn.XLOOKUP(B8,CRN!G:G,CRN!U:U,"") -> 0 | AA8: =IF(X8=0,0,_xlfn.XLOOKUP(C8,CLIENT_CODE!B:B,CLIENT_CODE!P:P,0)) -> 0 | AB8: =_xlfn.XLOOKUP(B8,CRN!G:G,CRN!V:V,"") -> 0 | AC8: =IF(AB8=0,0,_xlfn.XLOOKUP(C8,CLIENT_CODE!B:B,CLIENT_CODE!R:R,0)) -> 0 | AD8: =SUM(E8,G8,I8,K8,M8,O8,Q8,S8,U8,W8,Y8,AA8,AC8,) -> 0
A9: 8 | B9: MTP-N-2526-004127 | E9: =IF(D9=0,0,_xlfn.XLOOKUP(C9,CLIENT_CODE!B:B,CLIENT_CODE!F:F,0)) -> 0 | F9: =_xlfn.XLOOKUP(B9,CRN!G:G,CRN!K:K,"") -> 0 | G9: =IF(F9=0,0,_xlfn.XLOOKUP(C9,CLIENT_CODE!B:B,CLIENT_CODE!G:G,0)) -> 0 | H9: =_xlfn.XLOOKUP(B9,CRN!G:G,CRN!L:L,"") -> 1 | I9: =IF(H9=0,0,_xlfn.XLOOKUP(C9,CLIENT_CODE!B:B,CLIENT_CODE!H:H,0)) -> 0 | J9: =_xlfn.XLOOKUP(B9,CRN!G:G,CRN!M:M,"") -> 1 | K9: =IF(J9=0,0,_xlfn.XLOOKUP(C9,CLIENT_CODE!B:B,CLIENT_CODE!I:I,0)) -> 0 | L9: =_xlfn.XLOOKUP(B9,CRN!G:G,CRN!N:N,"") -> 1 | M9: =IF(L9=0,0,_xlfn.XLOOKUP(C9,CLIENT_CODE!B:B,CLIENT_CODE!J:J,0)) -> 0 | N9: =_xlfn.XLOOKUP(B9,CRN!G:G,CRN!O:O,"") -> 1 | O9: =IF(N9=0,0,_xlfn.XLOOKUP(C9,CLIENT_CODE!B:B,CLIENT_CODE!K:K,0)) -> 0 | P9: =_xlfn.XLOOKUP(B9,CRN!G:G,CRN!P:P,"") -> 1 | Q9: =IF(P9=0,0,_xlfn.XLOOKUP(C9,CLIENT_CODE!B:B,CLIENT_CODE!L:L,0)) -> 0 | R9: =_xlfn.XLOOKUP(B9,CRN!G:G,CRN!Q:Q,"") -> 0 | S9: =IF(R9=0,0,_xlfn.XLOOKUP(C9,CLIENT_CODE!B:B,CLIENT_CODE!M:M,0)) -> 0 | T9: =_xlfn.XLOOKUP(B9,CRN!G:G,CRN!R:R,"") -> 1 | U9: =IF(T9=0,0,_xlfn.XLOOKUP(C9,CLIENT_CODE!B:B,CLIENT_CODE!N:N,0)) -> 0 | V9: =_xlfn.XLOOKUP(B9,CRN!G:G,CRN!S:S,"") -> 1 | W9: =IF(V9=0,0,_xlfn.XLOOKUP(C9,CLIENT_CODE!B:B,CLIENT_CODE!O:O,0)) -> 0 | X9: =_xlfn.XLOOKUP(B9,CRN!G:G,CRN!T:T,"") -> 0 | Y9: =IF(X9=0,0,_xlfn.XLOOKUP(C9,CLIENT_CODE!B:B,CLIENT_CODE!P:P,0)) -> 0 | Z9: =_xlfn.XLOOKUP(B9,CRN!G:G,CRN!U:U,"") -> 0 | AA9: =IF(X9=0,0,_xlfn.XLOOKUP(C9,CLIENT_CODE!B:B,CLIENT_CODE!P:P,0)) -> 0 | AB9: =_xlfn.XLOOKUP(B9,CRN!G:G,CRN!V:V,"") -> 1 | AC9: =IF(AB9=0,0,_xlfn.XLOOKUP(C9,CLIENT_CODE!B:B,CLIENT_CODE!R:R,0)) -> 0 | AD9: =SUM(E9,G9,I9,K9,M9,O9,Q9,S9,U9,W9,Y9,AA9,AC9,) -> 0
A10: 9 | B10: 2025212058 | E10: =IF(D10=0,0,_xlfn.XLOOKUP(C10,CLIENT_CODE!B:B,CLIENT_CODE!F:F,0)) -> 0 | F10: =_xlfn.XLOOKUP(B10,CRN!G:G,CRN!K:K,"") -> 0 | G10: =IF(F10=0,0,_xlfn.XLOOKUP(C10,CLIENT_CODE!B:B,CLIENT_CODE!G:G,0)) -> 0 | H10: =_xlfn.XLOOKUP(B10,CRN!G:G,CRN!L:L,"") -> 1 | I10: =IF(H10=0,0,_xlfn.XLOOKUP(C10,CLIENT_CODE!B:B,CLIENT_CODE!H:H,0)) -> 0 | J10: =_xlfn.XLOOKUP(B10,CRN!G:G,CRN!M:M,"") -> 0 | K10: =IF(J10=0,0,_xlfn.XLOOKUP(C10,CLIENT_CODE!B:B,CLIENT_CODE!I:I,0)) -> 0 | L10: =_xlfn.XLOOKUP(B10,CRN!G:G,CRN!N:N,"") -> 1 | M10: =IF(L10=0,0,_xlfn.XLOOKUP(C10,CLIENT_CODE!B:B,CLIENT_CODE!J:J,0)) -> 0 | N10: =_xlfn.XLOOKUP(B10,CRN!G:G,CRN!O:O,"") -> 0 | O10: =IF(N10=0,0,_xlfn.XLOOKUP(C10,CLIENT_CODE!B:B,CLIENT_CODE!K:K,0)) -> 0 | P10: =_xlfn.XLOOKUP(B10,CRN!G:G,CRN!P:P,"") -> 0 | Q10: =IF(P10=0,0,_xlfn.XLOOKUP(C10,CLIENT_CODE!B:B,CLIENT_CODE!L:L,0)) -> 0 | R10: =_xlfn.XLOOKUP(B10,CRN!G:G,CRN!Q:Q,"") -> 0 | S10: =IF(R10=0,0,_xlfn.XLOOKUP(C10,CLIENT_CODE!B:B,CLIENT_CODE!M:M,0)) -> 0 | T10: =_xlfn.XLOOKUP(B10,CRN!G:G,CRN!R:R,"") -> 1 | U10: =IF(T10=0,0,_xlfn.XLOOKUP(C10,CLIENT_CODE!B:B,CLIENT_CODE!N:N,0)) -> 0 | V10: =_xlfn.XLOOKUP(B10,CRN!G:G,CRN!S:S,"") -> 1 | W10: =IF(V10=0,0,_xlfn.XLOOKUP(C10,CLIENT_CODE!B:B,CLIENT_CODE!O:O,0)) -> 0 | X10: =_xlfn.XLOOKUP(B10,CRN!G:G,CRN!T:T,"") -> 0 | Y10: =IF(X10=0,0,_xlfn.XLOOKUP(C10,CLIENT_CODE!B:B,CLIENT_CODE!P:P,0)) -> 0 | Z10: =_xlfn.XLOOKUP(B10,CRN!G:G,CRN!U:U,"") -> 0 | AA10: =IF(X10=0,0,_xlfn.XLOOKUP(C10,CLIENT_CODE!B:B,CLIENT_CODE!P:P,0)) -> 0 | AB10: =_xlfn.XLOOKUP(B10,CRN!G:G,CRN!V:V,"") -> 0 | AC10: =IF(AB10=0,0,_xlfn.XLOOKUP(C10,CLIENT_CODE!B:B,CLIENT_CODE!R:R,0)) -> 0 | AD10: =SUM(E10,G10,I10,K10,M10,O10,Q10,S10,U10,W10,Y10,AA10,AC10,) -> 0
A11: 10 | B11: 2025212055 | E11: =IF(D11=0,0,_xlfn.XLOOKUP(C11,CLIENT_CODE!B:B,CLIENT_CODE!F:F,0)) -> 0 | F11: =_xlfn.XLOOKUP(B11,CRN!G:G,CRN!K:K,"") -> 0 | G11: =IF(F11=0,0,_xlfn.XLOOKUP(C11,CLIENT_CODE!B:B,CLIENT_CODE!G:G,0)) -> 0 | H11: =_xlfn.XLOOKUP(B11,CRN!G:G,CRN!L:L,"") -> 1 | I11: =IF(H11=0,0,_xlfn.XLOOKUP(C11,CLIENT_CODE!B:B,CLIENT_CODE!H:H,0)) -> 0 | J11: =_xlfn.XLOOKUP(B11,CRN!G:G,CRN!M:M,"") -> 0 | K11: =IF(J11=0,0,_xlfn.XLOOKUP(C11,CLIENT_CODE!B:B,CLIENT_CODE!I:I,0)) -> 0 | L11: =_xlfn.XLOOKUP(B11,CRN!G:G,CRN!N:N,"") -> 0 | M11: =IF(L11=0,0,_xlfn.XLOOKUP(C11,CLIENT_CODE!B:B,CLIENT_CODE!J:J,0)) -> 0 | N11: =_xlfn.XLOOKUP(B11,CRN!G:G,CRN!O:O,"") -> 0 | O11: =IF(N11=0,0,_xlfn.XLOOKUP(C11,CLIENT_CODE!B:B,CLIENT_CODE!K:K,0)) -> 0 | P11: =_xlfn.XLOOKUP(B11,CRN!G:G,CRN!P:P,"") -> 0 | Q11: =IF(P11=0,0,_xlfn.XLOOKUP(C11,CLIENT_CODE!B:B,CLIENT_CODE!L:L,0)) -> 0 | R11: =_xlfn.XLOOKUP(B11,CRN!G:G,CRN!Q:Q,"") -> 0 | S11: =IF(R11=0,0,_xlfn.XLOOKUP(C11,CLIENT_CODE!B:B,CLIENT_CODE!M:M,0)) -> 0 | T11: =_xlfn.XLOOKUP(B11,CRN!G:G,CRN!R:R,"") -> 0 | U11: =IF(T11=0,0,_xlfn.XLOOKUP(C11,CLIENT_CODE!B:B,CLIENT_CODE!N:N,0)) -> 0 | V11: =_xlfn.XLOOKUP(B11,CRN!G:G,CRN!S:S,"") -> 0 | W11: =IF(V11=0,0,_xlfn.XLOOKUP(C11,CLIENT_CODE!B:B,CLIENT_CODE!O:O,0)) -> 0 | X11: =_xlfn.XLOOKUP(B11,CRN!G:G,CRN!T:T,"") -> 0 | Y11: =IF(X11=0,0,_xlfn.XLOOKUP(C11,CLIENT_CODE!B:B,CLIENT_CODE!P:P,0)) -> 0 | Z11: =_xlfn.XLOOKUP(B11,CRN!G:G,CRN!U:U,"") -> 0 | AA11: =IF(X11=0,0,_xlfn.XLOOKUP(C11,CLIENT_CODE!B:B,CLIENT_CODE!P:P,0)) -> 0 | AB11: =_xlfn.XLOOKUP(B11,CRN!G:G,CRN!V:V,"") -> 0 | AC11: =IF(AB11=0,0,_xlfn.XLOOKUP(C11,CLIENT_CODE!B:B,CLIENT_CODE!R:R,0)) -> 0 | AD11: =SUM(E11,G11,I11,K11,M11,O11,Q11,S11,U11,W11,Y11,AA11,AC11,) -> 0
A12: 11 | B12: 2025212053 | E12: =IF(D12=0,0,_xlfn.XLOOKUP(C12,CLIENT_CODE!B:B,CLIENT_CODE!F:F,0)) -> 0 | F12: =_xlfn.XLOOKUP(B12,CRN!G:G,CRN!K:K,"") -> 0 | G12: =IF(F12=0,0,_xlfn.XLOOKUP(C12,CLIENT_CODE!B:B,CLIENT_CODE!G:G,0)) -> 0 | H12: =_xlfn.XLOOKUP(B12,CRN!G:G,CRN!L:L,"") -> 1 | I12: =IF(H12=0,0,_xlfn.XLOOKUP(C12,CLIENT_CODE!B:B,CLIENT_CODE!H:H,0)) -> 0 | J12: =_xlfn.XLOOKUP(B12,CRN!G:G,CRN!M:M,"") -> 0 | K12: =IF(J12=0,0,_xlfn.XLOOKUP(C12,CLIENT_CODE!B:B,CLIENT_CODE!I:I,0)) -> 0 | L12: =_xlfn.XLOOKUP(B12,CRN!G:G,CRN!N:N,"") -> 1 | M12: =IF(L12=0,0,_xlfn.XLOOKUP(C12,CLIENT_CODE!B:B,CLIENT_CODE!J:J,0)) -> 0 | N12: =_xlfn.XLOOKUP(B12,CRN!G:G,CRN!O:O,"") -> 0 | O12: =IF(N12=0,0,_xlfn.XLOOKUP(C12,CLIENT_CODE!B:B,CLIENT_CODE!K:K,0)) -> 0 | P12: =_xlfn.XLOOKUP(B12,CRN!G:G,CRN!P:P,"") -> 0 | Q12: =IF(P12=0,0,_xlfn.XLOOKUP(C12,CLIENT_CODE!B:B,CLIENT_CODE!L:L,0)) -> 0 | R12: =_xlfn.XLOOKUP(B12,CRN!G:G,CRN!Q:Q,"") -> 0 | S12: =IF(R12=0,0,_xlfn.XLOOKUP(C12,CLIENT_CODE!B:B,CLIENT_CODE!M:M,0)) -> 0 | T12: =_xlfn.XLOOKUP(B12,CRN!G:G,CRN!R:R,"") -> 1 | U12: =IF(T12=0,0,_xlfn.XLOOKUP(C12,CLIENT_CODE!B:B,CLIENT_CODE!N:N,0)) -> 0 | V12: =_xlfn.XLOOKUP(B12,CRN!G:G,CRN!S:S,"") -> 1 | W12: =IF(V12=0,0,_xlfn.XLOOKUP(C12,CLIENT_CODE!B:B,CLIENT_CODE!O:O,0)) -> 0 | X12: =_xlfn.XLOOKUP(B12,CRN!G:G,CRN!T:T,"") -> 0 | Y12: =IF(X12=0,0,_xlfn.XLOOKUP(C12,CLIENT_CODE!B:B,CLIENT_CODE!P:P,0)) -> 0 | Z12: =_xlfn.XLOOKUP(B12,CRN!G:G,CRN!U:U,"") -> 0 | AA12: =IF(X12=0,0,_xlfn.XLOOKUP(C12,CLIENT_CODE!B:B,CLIENT_CODE!P:P,0)) -> 0 | AB12: =_xlfn.XLOOKUP(B12,CRN!G:G,CRN!V:V,"") -> 0 | AC12: =IF(AB12=0,0,_xlfn.XLOOKUP(C12,CLIENT_CODE!B:B,CLIENT_CODE!R:R,0)) -> 0 | AD12: =SUM(E12,G12,I12,K12,M12,O12,Q12,S12,U12,W12,Y12,AA12,AC12,) -> 0
A13: 12 | B13: 2025212050 | E13: =IF(D13=0,0,_xlfn.XLOOKUP(C13,CLIENT_CODE!B:B,CLIENT_CODE!F:F,0)) -> 0 | F13: =_xlfn.XLOOKUP(B13,CRN!G:G,CRN!K:K,"") -> 0 | G13: =IF(F13=0,0,_xlfn.XLOOKUP(C13,CLIENT_CODE!B:B,CLIENT_CODE!G:G,0)) -> 0 | H13: =_xlfn.XLOOKUP(B13,CRN!G:G,CRN!L:L,"") -> 1 | I13: =IF(H13=0,0,_xlfn.XLOOKUP(C13,CLIENT_CODE!B:B,CLIENT_CODE!H:H,0)) -> 0 | J13: =_xlfn.XLOOKUP(B13,CRN!G:G,CRN!M:M,"") -> 0 | K13: =IF(J13=0,0,_xlfn.XLOOKUP(C13,CLIENT_CODE!B:B,CLIENT_CODE!I:I,0)) -> 0 | L13: =_xlfn.XLOOKUP(B13,CRN!G:G,CRN!N:N,"") -> 1 | M13: =IF(L13=0,0,_xlfn.XLOOKUP(C13,CLIENT_CODE!B:B,CLIENT_CODE!J:J,0)) -> 0 | N13: =_xlfn.XLOOKUP(B13,CRN!G:G,CRN!O:O,"") -> 0 | O13: =IF(N13=0,0,_xlfn.XLOOKUP(C13,CLIENT_CODE!B:B,CLIENT_CODE!K:K,0)) -> 0 | P13: =_xlfn.XLOOKUP(B13,CRN!G:G,CRN!P:P,"") -> 0 | Q13: =IF(P13=0,0,_xlfn.XLOOKUP(C13,CLIENT_CODE!B:B,CLIENT_CODE!L:L,0)) -> 0 | R13: =_xlfn.XLOOKUP(B13,CRN!G:G,CRN!Q:Q,"") -> 0 | S13: =IF(R13=0,0,_xlfn.XLOOKUP(C13,CLIENT_CODE!B:B,CLIENT_CODE!M:M,0)) -> 0 | T13: =_xlfn.XLOOKUP(B13,CRN!G:G,CRN!R:R,"") -> 1 | U13: =IF(T13=0,0,_xlfn.XLOOKUP(C13,CLIENT_CODE!B:B,CLIENT_CODE!N:N,0)) -> 0 | V13: =_xlfn.XLOOKUP(B13,CRN!G:G,CRN!S:S,"") -> 1 | W13: =IF(V13=0,0,_xlfn.XLOOKUP(C13,CLIENT_CODE!B:B,CLIENT_CODE!O:O,0)) -> 0 | X13: =_xlfn.XLOOKUP(B13,CRN!G:G,CRN!T:T,"") -> 0 | Y13: =IF(X13=0,0,_xlfn.XLOOKUP(C13,CLIENT_CODE!B:B,CLIENT_CODE!P:P,0)) -> 0 | Z13: =_xlfn.XLOOKUP(B13,CRN!G:G,CRN!U:U,"") -> 0 | AA13: =IF(X13=0,0,_xlfn.XLOOKUP(C13,CLIENT_CODE!B:B,CLIENT_CODE!P:P,0)) -> 0 | AB13: =_xlfn.XLOOKUP(B13,CRN!G:G,CRN!V:V,"") -> 0 | AC13: =IF(AB13=0,0,_xlfn.XLOOKUP(C13,CLIENT_CODE!B:B,CLIENT_CODE!R:R,0)) -> 0 | AD13: =SUM(E13,G13,I13,K13,M13,O13,Q13,S13,U13,W13,Y13,AA13,AC13,) -> 0
A14: 13 | B14: 2025212191 | E14: =IF(D14=0,0,_xlfn.XLOOKUP(C14,CLIENT_CODE!B:B,CLIENT_CODE!F:F,0)) -> 0 | F14: =_xlfn.XLOOKUP(B14,CRN!G:G,CRN!K:K,"") -> 0 | G14: =IF(F14=0,0,_xlfn.XLOOKUP(C14,CLIENT_CODE!B:B,CLIENT_CODE!G:G,0)) -> 0 | H14: =_xlfn.XLOOKUP(B14,CRN!G:G,CRN!L:L,"") -> 1 | I14: =IF(H14=0,0,_xlfn.XLOOKUP(C14,CLIENT_CODE!B:B,CLIENT_CODE!H:H,0)) -> 0 | J14: =_xlfn.XLOOKUP(B14,CRN!G:G,CRN!M:M,"") -> 0 | K14: =IF(J14=0,0,_xlfn.XLOOKUP(C14,CLIENT_CODE!B:B,CLIENT_CODE!I:I,0)) -> 0 | L14: =_xlfn.XLOOKUP(B14,CRN!G:G,CRN!N:N,"") -> 1 | M14: =IF(L14=0,0,_xlfn.XLOOKUP(C14,CLIENT_CODE!B:B,CLIENT_CODE!J:J,0)) -> 0 | N14: =_xlfn.XLOOKUP(B14,CRN!G:G,CRN!O:O,"") -> 0 | O14: =IF(N14=0,0,_xlfn.XLOOKUP(C14,CLIENT_CODE!B:B,CLIENT_CODE!K:K,0)) -> 0 | P14: =_xlfn.XLOOKUP(B14,CRN!G:G,CRN!P:P,"") -> 0 | Q14: =IF(P14=0,0,_xlfn.XLOOKUP(C14,CLIENT_CODE!B:B,CLIENT_CODE!L:L,0)) -> 0 | R14: =_xlfn.XLOOKUP(B14,CRN!G:G,CRN!Q:Q,"") -> 0 | S14: =IF(R14=0,0,_xlfn.XLOOKUP(C14,CLIENT_CODE!B:B,CLIENT_CODE!M:M,0)) -> 0 | T14: =_xlfn.XLOOKUP(B14,CRN!G:G,CRN!R:R,"") -> 1 | U14: =IF(T14=0,0,_xlfn.XLOOKUP(C14,CLIENT_CODE!B:B,CLIENT_CODE!N:N,0)) -> 0 | V14: =_xlfn.XLOOKUP(B14,CRN!G:G,CRN!S:S,"") -> 1 | W14: =IF(V14=0,0,_xlfn.XLOOKUP(C14,CLIENT_CODE!B:B,CLIENT_CODE!O:O,0)) -> 0 | X14: =_xlfn.XLOOKUP(B14,CRN!G:G,CRN!T:T,"") -> 0 | Y14: =IF(X14=0,0,_xlfn.XLOOKUP(C14,CLIENT_CODE!B:B,CLIENT_CODE!P:P,0)) -> 0 | Z14: =_xlfn.XLOOKUP(B14,CRN!G:G,CRN!U:U,"") -> 0 | AA14: =IF(X14=0,0,_xlfn.XLOOKUP(C14,CLIENT_CODE!B:B,CLIENT_CODE!P:P,0)) -> 0 | AB14: =_xlfn.XLOOKUP(B14,CRN!G:G,CRN!V:V,"") -> 0 | AC14: =IF(AB14=0,0,_xlfn.XLOOKUP(C14,CLIENT_CODE!B:B,CLIENT_CODE!R:R,0)) -> 0 | AD14: =SUM(E14,G14,I14,K14,M14,O14,Q14,S14,U14,W14,Y14,AA14,AC14,) -> 0
A15: 14 | B15: 2025212189 | E15: =IF(D15=0,0,_xlfn.XLOOKUP(C15,CLIENT_CODE!B:B,CLIENT_CODE!F:F,0)) -> 0 | F15: =_xlfn.XLOOKUP(B15,CRN!G:G,CRN!K:K,"") -> 0 | G15: =IF(F15=0,0,_xlfn.XLOOKUP(C15,CLIENT_CODE!B:B,CLIENT_CODE!G:G,0)) -> 0 | H15: =_xlfn.XLOOKUP(B15,CRN!G:G,CRN!L:L,"") -> 1 | I15: =IF(H15=0,0,_xlfn.XLOOKUP(C15,CLIENT_CODE!B:B,CLIENT_CODE!H:H,0)) -> 0 | J15: =_xlfn.XLOOKUP(B15,CRN!G:G,CRN!M:M,"") -> 0 | K15: =IF(J15=0,0,_xlfn.XLOOKUP(C15,CLIENT_CODE!B:B,CLIENT_CODE!I:I,0)) -> 0 | L15: =_xlfn.XLOOKUP(B15,CRN!G:G,CRN!N:N,"") -> 1 | M15: =IF(L15=0,0,_xlfn.XLOOKUP(C15,CLIENT_CODE!B:B,CLIENT_CODE!J:J,0)) -> 0 | N15: =_xlfn.XLOOKUP(B15,CRN!G:G,CRN!O:O,"") -> 0 | O15: =IF(N15=0,0,_xlfn.XLOOKUP(C15,CLIENT_CODE!B:B,CLIENT_CODE!K:K,0)) -> 0 | P15: =_xlfn.XLOOKUP(B15,CRN!G:G,CRN!P:P,"") -> 0 | Q15: =IF(P15=0,0,_xlfn.XLOOKUP(C15,CLIENT_CODE!B:B,CLIENT_CODE!L:L,0)) -> 0 | R15: =_xlfn.XLOOKUP(B15,CRN!G:G,CRN!Q:Q,"") -> 0 | S15: =IF(R15=0,0,_xlfn.XLOOKUP(C15,CLIENT_CODE!B:B,CLIENT_CODE!M:M,0)) -> 0 | T15: =_xlfn.XLOOKUP(B15,CRN!G:G,CRN!R:R,"") -> 1 | U15: =IF(T15=0,0,_xlfn.XLOOKUP(C15,CLIENT_CODE!B:B,CLIENT_CODE!N:N,0)) -> 0 | V15: =_xlfn.XLOOKUP(B15,CRN!G:G,CRN!S:S,"") -> 1 | W15: =IF(V15=0,0,_xlfn.XLOOKUP(C15,CLIENT_CODE!B:B,CLIENT_CODE!O:O,0)) -> 0 | X15: =_xlfn.XLOOKUP(B15,CRN!G:G,CRN!T:T,"") -> 0 | Y15: =IF(X15=0,0,_xlfn.XLOOKUP(C15,CLIENT_CODE!B:B,CLIENT_CODE!P:P,0)) -> 0 | Z15: =_xlfn.XLOOKUP(B15,CRN!G:G,CRN!U:U,"") -> 0 | AA15: =IF(X15=0,0,_xlfn.XLOOKUP(C15,CLIENT_CODE!B:B,CLIENT_CODE!P:P,0)) -> 0 | AB15: =_xlfn.XLOOKUP(B15,CRN!G:G,CRN!V:V,"") -> 0 | AC15: =IF(AB15=0,0,_xlfn.XLOOKUP(C15,CLIENT_CODE!B:B,CLIENT_CODE!R:R,0)) -> 0 | AD15: =SUM(E15,G15,I15,K15,M15,O15,Q15,S15,U15,W15,Y15,AA15,AC15,) -> 0
A16: 15 | B16: 2025212222 | E16: =IF(D16=0,0,_xlfn.XLOOKUP(C16,CLIENT_CODE!B:B,CLIENT_CODE!F:F,0)) -> 0 | F16: =_xlfn.XLOOKUP(B16,CRN!G:G,CRN!K:K,"") -> 0 | G16: =IF(F16=0,0,_xlfn.XLOOKUP(C16,CLIENT_CODE!B:B,CLIENT_CODE!G:G,0)) -> 0 | H16: =_xlfn.XLOOKUP(B16,CRN!G:G,CRN!L:L,"") -> 1 | I16: =IF(H16=0,0,_xlfn.XLOOKUP(C16,CLIENT_CODE!B:B,CLIENT_CODE!H:H,0)) -> 0 | J16: =_xlfn.XLOOKUP(B16,CRN!G:G,CRN!M:M,"") -> 0 | K16: =IF(J16=0,0,_xlfn.XLOOKUP(C16,CLIENT_CODE!B:B,CLIENT_CODE!I:I,0)) -> 0 | L16: =_xlfn.XLOOKUP(B16,CRN!G:G,CRN!N:N,"") -> 0 | M16: =IF(L16=0,0,_xlfn.XLOOKUP(C16,CLIENT_CODE!B:B,CLIENT_CODE!J:J,0)) -> 0 | N16: =_xlfn.XLOOKUP(B16,CRN!G:G,CRN!O:O,"") -> 0 | O16: =IF(N16=0,0,_xlfn.XLOOKUP(C16,CLIENT_CODE!B:B,CLIENT_CODE!K:K,0)) -> 0 | P16: =_xlfn.XLOOKUP(B16,CRN!G:G,CRN!P:P,"") -> 0 | Q16: =IF(P16=0,0,_xlfn.XLOOKUP(C16,CLIENT_CODE!B:B,CLIENT_CODE!L:L,0)) -> 0 | R16: =_xlfn.XLOOKUP(B16,CRN!G:G,CRN!Q:Q,"") -> 0 | S16: =IF(R16=0,0,_xlfn.XLOOKUP(C16,CLIENT_CODE!B:B,CLIENT_CODE!M:M,0)) -> 0 | T16: =_xlfn.XLOOKUP(B16,CRN!G:G,CRN!R:R,"") -> 0 | U16: =IF(T16=0,0,_xlfn.XLOOKUP(C16,CLIENT_CODE!B:B,CLIENT_CODE!N:N,0)) -> 0 | V16: =_xlfn.XLOOKUP(B16,CRN!G:G,CRN!S:S,"") -> 0 | W16: =IF(V16=0,0,_xlfn.XLOOKUP(C16,CLIENT_CODE!B:B,CLIENT_CODE!O:O,0)) -> 0 | X16: =_xlfn.XLOOKUP(B16,CRN!G:G,CRN!T:T,"") -> 0 | Y16: =IF(X16=0,0,_xlfn.XLOOKUP(C16,CLIENT_CODE!B:B,CLIENT_CODE!P:P,0)) -> 0 | Z16: =_xlfn.XLOOKUP(B16,CRN!G:G,CRN!U:U,"") -> 0 | AA16: =IF(X16=0,0,_xlfn.XLOOKUP(C16,CLIENT_CODE!B:B,CLIENT_CODE!P:P,0)) -> 0 | AB16: =_xlfn.XLOOKUP(B16,CRN!G:G,CRN!V:V,"") -> 0 | AC16: =IF(AB16=0,0,_xlfn.XLOOKUP(C16,CLIENT_CODE!B:B,CLIENT_CODE!R:R,0)) -> 0 | AD16: =SUM(E16,G16,I16,K16,M16,O16,Q16,S16,U16,W16,Y16,AA16,AC16,) -> 0
A17: 16 | B17: 2025212162 | E17: =IF(D17=0,0,_xlfn.XLOOKUP(C17,CLIENT_CODE!B:B,CLIENT_CODE!F:F,0)) -> 0 | F17: =_xlfn.XLOOKUP(B17,CRN!G:G,CRN!K:K,"") -> 0 | G17: =IF(F17=0,0,_xlfn.XLOOKUP(C17,CLIENT_CODE!B:B,CLIENT_CODE!G:G,0)) -> 0 | H17: =_xlfn.XLOOKUP(B17,CRN!G:G,CRN!L:L,"") -> 1 | I17: =IF(H17=0,0,_xlfn.XLOOKUP(C17,CLIENT_CODE!B:B,CLIENT_CODE!H:H,0)) -> 0 | J17: =_xlfn.XLOOKUP(B17,CRN!G:G,CRN!M:M,"") -> 0 | K17: =IF(J17=0,0,_xlfn.XLOOKUP(C17,CLIENT_CODE!B:B,CLIENT_CODE!I:I,0)) -> 0 | L17: =_xlfn.XLOOKUP(B17,CRN!G:G,CRN!N:N,"") -> 0 | M17: =IF(L17=0,0,_xlfn.XLOOKUP(C17,CLIENT_CODE!B:B,CLIENT_CODE!J:J,0)) -> 0 | N17: =_xlfn.XLOOKUP(B17,CRN!G:G,CRN!O:O,"") -> 0 | O17: =IF(N17=0,0,_xlfn.XLOOKUP(C17,CLIENT_CODE!B:B,CLIENT_CODE!K:K,0)) -> 0 | P17: =_xlfn.XLOOKUP(B17,CRN!G:G,CRN!P:P,"") -> 0 | Q17: =IF(P17=0,0,_xlfn.XLOOKUP(C17,CLIENT_CODE!B:B,CLIENT_CODE!L:L,0)) -> 0 | R17: =_xlfn.XLOOKUP(B17,CRN!G:G,CRN!Q:Q,"") -> 0 | S17: =IF(R17=0,0,_xlfn.XLOOKUP(C17,CLIENT_CODE!B:B,CLIENT_CODE!M:M,0)) -> 0 | T17: =_xlfn.XLOOKUP(B17,CRN!G:G,CRN!R:R,"") -> 0 | U17: =IF(T17=0,0,_xlfn.XLOOKUP(C17,CLIENT_CODE!B:B,CLIENT_CODE!N:N,0)) -> 0 | V17: =_xlfn.XLOOKUP(B17,CRN!G:G,CRN!S:S,"") -> 0 | W17: =IF(V17=0,0,_xlfn.XLOOKUP(C17,CLIENT_CODE!B:B,CLIENT_CODE!O:O,0)) -> 0 | X17: =_xlfn.XLOOKUP(B17,CRN!G:G,CRN!T:T,"") -> 0 | Y17: =IF(X17=0,0,_xlfn.XLOOKUP(C17,CLIENT_CODE!B:B,CLIENT_CODE!P:P,0)) -> 0 | Z17: =_xlfn.XLOOKUP(B17,CRN!G:G,CRN!U:U,"") -> 0 | AA17: =IF(X17=0,0,_xlfn.XLOOKUP(C17,CLIENT_CODE!B:B,CLIENT_CODE!P:P,0)) -> 0 | AB17: =_xlfn.XLOOKUP(B17,CRN!G:G,CRN!V:V,"") -> 0 | AC17: =IF(AB17=0,0,_xlfn.XLOOKUP(C17,CLIENT_CODE!B:B,CLIENT_CODE!R:R,0)) -> 0 | AD17: =SUM(E17,G17,I17,K17,M17,O17,Q17,S17,U17,W17,Y17,AA17,AC17,) -> 0
A18: 17 | B18: 2025212410 | E18: =IF(D18=0,0,_xlfn.XLOOKUP(C18,CLIENT_CODE!B:B,CLIENT_CODE!F:F,0)) -> 0 | F18: =_xlfn.XLOOKUP(B18,CRN!G:G,CRN!K:K,"") -> 0 | G18: =IF(F18=0,0,_xlfn.XLOOKUP(C18,CLIENT_CODE!B:B,CLIENT_CODE!G:G,0)) -> 0 | H18: =_xlfn.XLOOKUP(B18,CRN!G:G,CRN!L:L,"") -> 1 | I18: =IF(H18=0,0,_xlfn.XLOOKUP(C18,CLIENT_CODE!B:B,CLIENT_CODE!H:H,0)) -> 0 | J18: =_xlfn.XLOOKUP(B18,CRN!G:G,CRN!M:M,"") -> 0 | K18: =IF(J18=0,0,_xlfn.XLOOKUP(C18,CLIENT_CODE!B:B,CLIENT_CODE!I:I,0)) -> 0 | L18: =_xlfn.XLOOKUP(B18,CRN!G:G,CRN!N:N,"") -> 1 | M18: =IF(L18=0,0,_xlfn.XLOOKUP(C18,CLIENT_CODE!B:B,CLIENT_CODE!J:J,0)) -> 0 | N18: =_xlfn.XLOOKUP(B18,CRN!G:G,CRN!O:O,"") -> 0 | O18: =IF(N18=0,0,_xlfn.XLOOKUP(C18,CLIENT_CODE!B:B,CLIENT_CODE!K:K,0)) -> 0 | P18: =_xlfn.XLOOKUP(B18,CRN!G:G,CRN!P:P,"") -> 0 | Q18: =IF(P18=0,0,_xlfn.XLOOKUP(C18,CLIENT_CODE!B:B,CLIENT_CODE!L:L,0)) -> 0 | R18: =_xlfn.XLOOKUP(B18,CRN!G:G,CRN!Q:Q,"") -> 0 | S18: =IF(R18=0,0,_xlfn.XLOOKUP(C18,CLIENT_CODE!B:B,CLIENT_CODE!M:M,0)) -> 0 | T18: =_xlfn.XLOOKUP(B18,CRN!G:G,CRN!R:R,"") -> 1 | U18: =IF(T18=0,0,_xlfn.XLOOKUP(C18,CLIENT_CODE!B:B,CLIENT_CODE!N:N,0)) -> 0 | V18: =_xlfn.XLOOKUP(B18,CRN!G:G,CRN!S:S,"") -> 1 | W18: =IF(V18=0,0,_xlfn.XLOOKUP(C18,CLIENT_CODE!B:B,CLIENT_CODE!O:O,0)) -> 0 | X18: =_xlfn.XLOOKUP(B18,CRN!G:G,CRN!T:T,"") -> 0 | Y18: =IF(X18=0,0,_xlfn.XLOOKUP(C18,CLIENT_CODE!B:B,CLIENT_CODE!P:P,0)) -> 0 | Z18: =_xlfn.XLOOKUP(B18,CRN!G:G,CRN!U:U,"") -> 0 | AA18: =IF(X18=0,0,_xlfn.XLOOKUP(C18,CLIENT_CODE!B:B,CLIENT_CODE!P:P,0)) -> 0 | AB18: =_xlfn.XLOOKUP(B18,CRN!G:G,CRN!V:V,"") -> 0 | AC18: =IF(AB18=0,0,_xlfn.XLOOKUP(C18,CLIENT_CODE!B:B,CLIENT_CODE!R:R,0)) -> 0 | AD18: =SUM(E18,G18,I18,K18,M18,O18,Q18,S18,U18,W18,Y18,AA18,AC18,) -> 0
A19: 18 | B19: 2025212215 | E19: =IF(D19=0,0,_xlfn.XLOOKUP(C19,CLIENT_CODE!B:B,CLIENT_CODE!F:F,0)) -> 0 | F19: =_xlfn.XLOOKUP(B19,CRN!G:G,CRN!K:K,"") -> 0 | G19: =IF(F19=0,0,_xlfn.XLOOKUP(C19,CLIENT_CODE!B:B,CLIENT_CODE!G:G,0)) -> 0 | H19: =_xlfn.XLOOKUP(B19,CRN!G:G,CRN!L:L,"") -> 1 | I19: =IF(H19=0,0,_xlfn.XLOOKUP(C19,CLIENT_CODE!B:B,CLIENT_CODE!H:H,0)) -> 0 | J19: =_xlfn.XLOOKUP(B19,CRN!G:G,CRN!M:M,"") -> 0 | K19: =IF(J19=0,0,_xlfn.XLOOKUP(C19,CLIENT_CODE!B:B,CLIENT_CODE!I:I,0)) -> 0 | L19: =_xlfn.XLOOKUP(B19,CRN!G:G,CRN!N:N,"") -> 1 | M19: =IF(L19=0,0,_xlfn.XLOOKUP(C19,CLIENT_CODE!B:B,CLIENT_CODE!J:J,0)) -> 0 | N19: =_xlfn.XLOOKUP(B19,CRN!G:G,CRN!O:O,"") -> 0 | O19: =IF(N19=0,0,_xlfn.XLOOKUP(C19,CLIENT_CODE!B:B,CLIENT_CODE!K:K,0)) -> 0 | P19: =_xlfn.XLOOKUP(B19,CRN!G:G,CRN!P:P,"") -> 0 | Q19: =IF(P19=0,0,_xlfn.XLOOKUP(C19,CLIENT_CODE!B:B,CLIENT_CODE!L:L,0)) -> 0 | R19: =_xlfn.XLOOKUP(B19,CRN!G:G,CRN!Q:Q,"") -> 0 | S19: =IF(R19=0,0,_xlfn.XLOOKUP(C19,CLIENT_CODE!B:B,CLIENT_CODE!M:M,0)) -> 0 | T19: =_xlfn.XLOOKUP(B19,CRN!G:G,CRN!R:R,"") -> 1 | U19: =IF(T19=0,0,_xlfn.XLOOKUP(C19,CLIENT_CODE!B:B,CLIENT_CODE!N:N,0)) -> 0 | V19: =_xlfn.XLOOKUP(B19,CRN!G:G,CRN!S:S,"") -> 1 | W19: =IF(V19=0,0,_xlfn.XLOOKUP(C19,CLIENT_CODE!B:B,CLIENT_CODE!O:O,0)) -> 0 | X19: =_xlfn.XLOOKUP(B19,CRN!G:G,CRN!T:T,"") -> 0 | Y19: =IF(X19=0,0,_xlfn.XLOOKUP(C19,CLIENT_CODE!B:B,CLIENT_CODE!P:P,0)) -> 0 | Z19: =_xlfn.XLOOKUP(B19,CRN!G:G,CRN!U:U,"") -> 0 | AA19: =IF(X19=0,0,_xlfn.XLOOKUP(C19,CLIENT_CODE!B:B,CLIENT_CODE!P:P,0)) -> 0 | AB19: =_xlfn.XLOOKUP(B19,CRN!G:G,CRN!V:V,"") -> 0 | AC19: =IF(AB19=0,0,_xlfn.XLOOKUP(C19,CLIENT_CODE!B:B,CLIENT_CODE!R:R,0)) -> 0 | AD19: =SUM(E19,G19,I19,K19,M19,O19,Q19,S19,U19,W19,Y19,AA19,AC19,) -> 0
A20: 19 | B20: 2025212407 | E20: =IF(D20=0,0,_xlfn.XLOOKUP(C20,CLIENT_CODE!B:B,CLIENT_CODE!F:F,0)) -> 0 | F20: =_xlfn.XLOOKUP(B20,CRN!G:G,CRN!K:K,"") -> 0 | G20: =IF(F20=0,0,_xlfn.XLOOKUP(C20,CLIENT_CODE!B:B,CLIENT_CODE!G:G,0)) -> 0 | H20: =_xlfn.XLOOKUP(B20,CRN!G:G,CRN!L:L,"") -> 1 | I20: =IF(H20=0,0,_xlfn.XLOOKUP(C20,CLIENT_CODE!B:B,CLIENT_CODE!H:H,0)) -> 0 | J20: =_xlfn.XLOOKUP(B20,CRN!G:G,CRN!M:M,"") -> 0 | K20: =IF(J20=0,0,_xlfn.XLOOKUP(C20,CLIENT_CODE!B:B,CLIENT_CODE!I:I,0)) -> 0 | L20: =_xlfn.XLOOKUP(B20,CRN!G:G,CRN!N:N,"") -> 0 | M20: =IF(L20=0,0,_xlfn.XLOOKUP(C20,CLIENT_CODE!B:B,CLIENT_CODE!J:J,0)) -> 0 | N20: =_xlfn.XLOOKUP(B20,CRN!G:G,CRN!O:O,"") -> 0 | O20: =IF(N20=0,0,_xlfn.XLOOKUP(C20,CLIENT_CODE!B:B,CLIENT_CODE!K:K,0)) -> 0 | P20: =_xlfn.XLOOKUP(B20,CRN!G:G,CRN!P:P,"") -> 0 | Q20: =IF(P20=0,0,_xlfn.XLOOKUP(C20,CLIENT_CODE!B:B,CLIENT_CODE!L:L,0)) -> 0 | R20: =_xlfn.XLOOKUP(B20,CRN!G:G,CRN!Q:Q,"") -> 0 | S20: =IF(R20=0,0,_xlfn.XLOOKUP(C20,CLIENT_CODE!B:B,CLIENT_CODE!M:M,0)) -> 0 | T20: =_xlfn.XLOOKUP(B20,CRN!G:G,CRN!R:R,"") -> 0 | U20: =IF(T20=0,0,_xlfn.XLOOKUP(C20,CLIENT_CODE!B:B,CLIENT_CODE!N:N,0)) -> 0 | V20: =_xlfn.XLOOKUP(B20,CRN!G:G,CRN!S:S,"") -> 0 | W20: =IF(V20=0,0,_xlfn.XLOOKUP(C20,CLIENT_CODE!B:B,CLIENT_CODE!O:O,0)) -> 0 | X20: =_xlfn.XLOOKUP(B20,CRN!G:G,CRN!T:T,"") -> 0 | Y20: =IF(X20=0,0,_xlfn.XLOOKUP(C20,CLIENT_CODE!B:B,CLIENT_CODE!P:P,0)) -> 0 | Z20: =_xlfn.XLOOKUP(B20,CRN!G:G,CRN!U:U,"") -> 0 | AA20: =IF(X20=0,0,_xlfn.XLOOKUP(C20,CLIENT_CODE!B:B,CLIENT_CODE!P:P,0)) -> 0 | AB20: =_xlfn.XLOOKUP(B20,CRN!G:G,CRN!V:V,"") -> 0 | AC20: =IF(AB20=0,0,_xlfn.XLOOKUP(C20,CLIENT_CODE!B:B,CLIENT_CODE!R:R,0)) -> 0 | AD20: =SUM(E20,G20,I20,K20,M20,O20,Q20,S20,U20,W20,Y20,AA20,AC20,) -> 0
A21: 20 | B21: 2025212443 | E21: =IF(D21=0,0,_xlfn.XLOOKUP(C21,CLIENT_CODE!B:B,CLIENT_CODE!F:F,0)) -> 0 | F21: =_xlfn.XLOOKUP(B21,CRN!G:G,CRN!K:K,"") -> 0 | G21: =IF(F21=0,0,_xlfn.XLOOKUP(C21,CLIENT_CODE!B:B,CLIENT_CODE!G:G,0)) -> 0 | H21: =_xlfn.XLOOKUP(B21,CRN!G:G,CRN!L:L,"") -> 1 | I21: =IF(H21=0,0,_xlfn.XLOOKUP(C21,CLIENT_CODE!B:B,CLIENT_CODE!H:H,0)) -> 0 | J21: =_xlfn.XLOOKUP(B21,CRN!G:G,CRN!M:M,"") -> 0 | K21: =IF(J21=0,0,_xlfn.XLOOKUP(C21,CLIENT_CODE!B:B,CLIENT_CODE!I:I,0)) -> 0 | L21: =_xlfn.XLOOKUP(B21,CRN!G:G,CRN!N:N,"") -> 1 | M21: =IF(L21=0,0,_xlfn.XLOOKUP(C21,CLIENT_CODE!B:B,CLIENT_CODE!J:J,0)) -> 0 | N21: =_xlfn.XLOOKUP(B21,CRN!G:G,CRN!O:O,"") -> 0 | O21: =IF(N21=0,0,_xlfn.XLOOKUP(C21,CLIENT_CODE!B:B,CLIENT_CODE!K:K,0)) -> 0 | P21: =_xlfn.XLOOKUP(B21,CRN!G:G,CRN!P:P,"") -> 0 | Q21: =IF(P21=0,0,_xlfn.XLOOKUP(C21,CLIENT_CODE!B:B,CLIENT_CODE!L:L,0)) -> 0 | R21: =_xlfn.XLOOKUP(B21,CRN!G:G,CRN!Q:Q,"") -> 0 | S21: =IF(R21=0,0,_xlfn.XLOOKUP(C21,CLIENT_CODE!B:B,CLIENT_CODE!M:M,0)) -> 0 | T21: =_xlfn.XLOOKUP(B21,CRN!G:G,CRN!R:R,"") -> 1 | U21: =IF(T21=0,0,_xlfn.XLOOKUP(C21,CLIENT_CODE!B:B,CLIENT_CODE!N:N,0)) -> 0 | V21: =_xlfn.XLOOKUP(B21,CRN!G:G,CRN!S:S,"") -> 1 | W21: =IF(V21=0,0,_xlfn.XLOOKUP(C21,CLIENT_CODE!B:B,CLIENT_CODE!O:O,0)) -> 0 | X21: =_xlfn.XLOOKUP(B21,CRN!G:G,CRN!T:T,"") -> 0 | Y21: =IF(X21=0,0,_xlfn.XLOOKUP(C21,CLIENT_CODE!B:B,CLIENT_CODE!P:P,0)) -> 0 | Z21: =_xlfn.XLOOKUP(B21,CRN!G:G,CRN!U:U,"") -> 0 | AA21: =IF(X21=0,0,_xlfn.XLOOKUP(C21,CLIENT_CODE!B:B,CLIENT_CODE!P:P,0)) -> 0 | AB21: =_xlfn.XLOOKUP(B21,CRN!G:G,CRN!V:V,"") -> 0 | AC21: =IF(AB21=0,0,_xlfn.XLOOKUP(C21,CLIENT_CODE!B:B,CLIENT_CODE!R:R,0)) -> 0 | AD21: =SUM(E21,G21,I21,K21,M21,O21,Q21,S21,U21,W21,Y21,AA21,AC21,) -> 0
A22: 21 | B22: 2025212467 | E22: =IF(D22=0,0,_xlfn.XLOOKUP(C22,CLIENT_CODE!B:B,CLIENT_CODE!F:F,0)) -> 0 | F22: =_xlfn.XLOOKUP(B22,CRN!G:G,CRN!K:K,"") -> 0 | G22: =IF(F22=0,0,_xlfn.XLOOKUP(C22,CLIENT_CODE!B:B,CLIENT_CODE!G:G,0)) -> 0 | H22: =_xlfn.XLOOKUP(B22,CRN!G:G,CRN!L:L,"") -> 1 | I22: =IF(H22=0,0,_xlfn.XLOOKUP(C22,CLIENT_CODE!B:B,CLIENT_CODE!H:H,0)) -> 0 | J22: =_xlfn.XLOOKUP(B22,CRN!G:G,CRN!M:M,"") -> 0 | K22: =IF(J22=0,0,_xlfn.XLOOKUP(C22,CLIENT_CODE!B:B,CLIENT_CODE!I:I,0)) -> 0 | L22: =_xlfn.XLOOKUP(B22,CRN!G:G,CRN!N:N,"") -> 1 | M22: =IF(L22=0,0,_xlfn.XLOOKUP(C22,CLIENT_CODE!B:B,CLIENT_CODE!J:J,0)) -> 0 | N22: =_xlfn.XLOOKUP(B22,CRN!G:G,CRN!O:O,"") -> 0 | O22: =IF(N22=0,0,_xlfn.XLOOKUP(C22,CLIENT_CODE!B:B,CLIENT_CODE!K:K,0)) -> 0 | P22: =_xlfn.XLOOKUP(B22,CRN!G:G,CRN!P:P,"") -> 0 | Q22: =IF(P22=0,0,_xlfn.XLOOKUP(C22,CLIENT_CODE!B:B,CLIENT_CODE!L:L,0)) -> 0 | R22: =_xlfn.XLOOKUP(B22,CRN!G:G,CRN!Q:Q,"") -> 0 | S22: =IF(R22=0,0,_xlfn.XLOOKUP(C22,CLIENT_CODE!B:B,CLIENT_CODE!M:M,0)) -> 0 | T22: =_xlfn.XLOOKUP(B22,CRN!G:G,CRN!R:R,"") -> 1 | U22: =IF(T22=0,0,_xlfn.XLOOKUP(C22,CLIENT_CODE!B:B,CLIENT_CODE!N:N,0)) -> 0 | V22: =_xlfn.XLOOKUP(B22,CRN!G:G,CRN!S:S,"") -> 1 | W22: =IF(V22=0,0,_xlfn.XLOOKUP(C22,CLIENT_CODE!B:B,CLIENT_CODE!O:O,0)) -> 0 | X22: =_xlfn.XLOOKUP(B22,CRN!G:G,CRN!T:T,"") -> 0 | Y22: =IF(X22=0,0,_xlfn.XLOOKUP(C22,CLIENT_CODE!B:B,CLIENT_CODE!P:P,0)) -> 0 | Z22: =_xlfn.XLOOKUP(B22,CRN!G:G,CRN!U:U,"") -> 0 | AA22: =IF(X22=0,0,_xlfn.XLOOKUP(C22,CLIENT_CODE!B:B,CLIENT_CODE!P:P,0)) -> 0 | AB22: =_xlfn.XLOOKUP(B22,CRN!G:G,CRN!V:V,"") -> 0 | AC22: =IF(AB22=0,0,_xlfn.XLOOKUP(C22,CLIENT_CODE!B:B,CLIENT_CODE!R:R,0)) -> 0 | AD22: =SUM(E22,G22,I22,K22,M22,O22,Q22,S22,U22,W22,Y22,AA22,AC22,) -> 0
A23: 22 | B23: 2024213743 | E23: =IF(D23=0,0,_xlfn.XLOOKUP(C23,CLIENT_CODE!B:B,CLIENT_CODE!F:F,0)) -> 0 | F23: =_xlfn.XLOOKUP(B23,CRN!G:G,CRN!K:K,"") -> 0 | G23: =IF(F23=0,0,_xlfn.XLOOKUP(C23,CLIENT_CODE!B:B,CLIENT_CODE!G:G,0)) -> 0 | H23: =_xlfn.XLOOKUP(B23,CRN!G:G,CRN!L:L,"") -> 0 | I23: =IF(H23=0,0,_xlfn.XLOOKUP(C23,CLIENT_CODE!B:B,CLIENT_CODE!H:H,0)) -> 0 | J23: =_xlfn.XLOOKUP(B23,CRN!G:G,CRN!M:M,"") -> 0 | K23: =IF(J23=0,0,_xlfn.XLOOKUP(C23,CLIENT_CODE!B:B,CLIENT_CODE!I:I,0)) -> 0 | L23: =_xlfn.XLOOKUP(B23,CRN!G:G,CRN!N:N,"") -> 0 | M23: =IF(L23=0,0,_xlfn.XLOOKUP(C23,CLIENT_CODE!B:B,CLIENT_CODE!J:J,0)) -> 0 | N23: =_xlfn.XLOOKUP(B23,CRN!G:G,CRN!O:O,"") -> 0 | O23: =IF(N23=0,0,_xlfn.XLOOKUP(C23,CLIENT_CODE!B:B,CLIENT_CODE!K:K,0)) -> 0 | P23: =_xlfn.XLOOKUP(B23,CRN!G:G,CRN!P:P,"") -> 0 | Q23: =IF(P23=0,0,_xlfn.XLOOKUP(C23,CLIENT_CODE!B:B,CLIENT_CODE!L:L,0)) -> 0 | R23: =_xlfn.XLOOKUP(B23,CRN!G:G,CRN!Q:Q,"") -> 0 | S23: =IF(R23=0,0,_xlfn.XLOOKUP(C23,CLIENT_CODE!B:B,CLIENT_CODE!M:M,0)) -> 0 | T23: =_xlfn.XLOOKUP(B23,CRN!G:G,CRN!R:R,"") -> 0 | U23: =IF(T23=0,0,_xlfn.XLOOKUP(C23,CLIENT_CODE!B:B,CLIENT_CODE!N:N,0)) -> 0 | V23: =_xlfn.XLOOKUP(B23,CRN!G:G,CRN!S:S,"") -> 1 | W23: =IF(V23=0,0,_xlfn.XLOOKUP(C23,CLIENT_CODE!B:B,CLIENT_CODE!O:O,0)) -> 0 | X23: =_xlfn.XLOOKUP(B23,CRN!G:G,CRN!T:T,"") -> 0 | Y23: =IF(X23=0,0,_xlfn.XLOOKUP(C23,CLIENT_CODE!B:B,CLIENT_CODE!P:P,0)) -> 0 | Z23: =_xlfn.XLOOKUP(B23,CRN!G:G,CRN!U:U,"") -> 0 | AA23: =IF(X23=0,0,_xlfn.XLOOKUP(C23,CLIENT_CODE!B:B,CLIENT_CODE!P:P,0)) -> 0 | AB23: =_xlfn.XLOOKUP(B23,CRN!G:G,CRN!V:V,"") -> 0 | AC23: =IF(AB23=0,0,_xlfn.XLOOKUP(C23,CLIENT_CODE!B:B,CLIENT_CODE!R:R,0)) -> 0 | AD23: =SUM(E23,G23,I23,K23,M23,O23,Q23,S23,U23,W23,Y23,AA23,AC23,) -> 0
A24: 23 | B24: 2025212533 | E24: =IF(D24=0,0,_xlfn.XLOOKUP(C24,CLIENT_CODE!B:B,CLIENT_CODE!F:F,0)) -> 0 | F24: =_xlfn.XLOOKUP(B24,CRN!G:G,CRN!K:K,"") -> 0 | G24: =IF(F24=0,0,_xlfn.XLOOKUP(C24,CLIENT_CODE!B:B,CLIENT_CODE!G:G,0)) -> 0 | H24: =_xlfn.XLOOKUP(B24,CRN!G:G,CRN!L:L,"") -> 1 | I24: =IF(H24=0,0,_xlfn.XLOOKUP(C24,CLIENT_CODE!B:B,CLIENT_CODE!H:H,0)) -> 0 | J24: =_xlfn.XLOOKUP(B24,CRN!G:G,CRN!M:M,"") -> 0 | K24: =IF(J24=0,0,_xlfn.XLOOKUP(C24,CLIENT_CODE!B:B,CLIENT_CODE!I:I,0)) -> 0 | L24: =_xlfn.XLOOKUP(B24,CRN!G:G,CRN!N:N,"") -> 1 | M24: =IF(L24=0,0,_xlfn.XLOOKUP(C24,CLIENT_CODE!B:B,CLIENT_CODE!J:J,0)) -> 0 | N24: =_xlfn.XLOOKUP(B24,CRN!G:G,CRN!O:O,"") -> 0 | O24: =IF(N24=0,0,_xlfn.XLOOKUP(C24,CLIENT_CODE!B:B,CLIENT_CODE!K:K,0)) -> 0 | P24: =_xlfn.XLOOKUP(B24,CRN!G:G,CRN!P:P,"") -> 0 | Q24: =IF(P24=0,0,_xlfn.XLOOKUP(C24,CLIENT_CODE!B:B,CLIENT_CODE!L:L,0)) -> 0 | R24: =_xlfn.XLOOKUP(B24,CRN!G:G,CRN!Q:Q,"") -> 0 | S24: =IF(R24=0,0,_xlfn.XLOOKUP(C24,CLIENT_CODE!B:B,CLIENT_CODE!M:M,0)) -> 0 | T24: =_xlfn.XLOOKUP(B24,CRN!G:G,CRN!R:R,"") -> 1 | U24: =IF(T24=0,0,_xlfn.XLOOKUP(C24,CLIENT_CODE!B:B,CLIENT_CODE!N:N,0)) -> 0 | V24: =_xlfn.XLOOKUP(B24,CRN!G:G,CRN!S:S,"") -> 1 | W24: =IF(V24=0,0,_xlfn.XLOOKUP(C24,CLIENT_CODE!B:B,CLIENT_CODE!O:O,0)) -> 0 | X24: =_xlfn.XLOOKUP(B24,CRN!G:G,CRN!T:T,"") -> 0 | Y24: =IF(X24=0,0,_xlfn.XLOOKUP(C24,CLIENT_CODE!B:B,CLIENT_CODE!P:P,0)) -> 0 | Z24: =_xlfn.XLOOKUP(B24,CRN!G:G,CRN!U:U,"") -> 0 | AA24: =IF(X24=0,0,_xlfn.XLOOKUP(C24,CLIENT_CODE!B:B,CLIENT_CODE!P:P,0)) -> 0 | AB24: =_xlfn.XLOOKUP(B24,CRN!G:G,CRN!V:V,"") -> 0 | AC24: =IF(AB24=0,0,_xlfn.XLOOKUP(C24,CLIENT_CODE!B:B,CLIENT_CODE!R:R,0)) -> 0 | AD24: =SUM(E24,G24,I24,K24,M24,O24,Q24,S24,U24,W24,Y24,AA24,AC24,) -> 0
